Workbook

Sheet 표지
B5: 2025년도 본예산(안)

Sheet 목차
A2: 목 차
D3: 1. 사업운영계획 | G3: ― ― ― ― ― ― ― ― ― ― ― ― ― ― ― ― ― ― ― ― ― ― ― ― ― ― ―
D4: 2. 예산총칙 | F4: ― ― ― ― ― ― ― ― ― ― ― ― ― ― ― ― ― ― ― ― ― ― ― ― ― ― ― ― ― ― ― ―
D5: 3. 예산총괄표 | F5: ― ― ― ― ― ― ― ― ― ― ― ― ― ― ― ― ― ― ― ― ― ― ― ― ― ― ― ― ― ― ― ―
E6: ㅇ 총괄 | G6: ― ― ― ― ― ― ― ― ― ― ― ― ― ― ― ― ― ― ― ― ― ― ― ― ― ― ―
E7: ㅇ 목별조서 | G7: ― ― ― ― ― ― ― ― ― ― ― ― ― ― ― ― ― ― ― ― ― ― ― ― ― ― ―
D8: 4. 사업예산
E9: ㅇ 사업예산 총괄표 | G9: ― ― ― ― ― ― ― ― ― ― ― ― ― ― ― ― ― ― ― ― ― ― ― ― ― ― ―
E10: ㅇ 수익적수입 | G10: ― ― ― ― ― ― ― ― ― ― ― ― ― ― ― ― ― ― ― ― ― ― ― ― ― ― ―
E11: ㅇ 수익적지출 | G11: ― ― ― ― ― ― ― ― ― ― ― ― ― ― ― ― ― ― ― ― ― ― ― ― ― ― ―
D12: 5. 자본예산
E13: ㅇ 자본예산총괄표 | G13: ― ― ― ― ― ― ― ― ― ― ― ― ― ― ― ― ― ― ― ― ― ― ― ― ― ― ―
E14: ㅇ 자본적수입 | G14: ― ― ― ― ― ― ― ― ― ― ― ― ― ― ― ― ― ― ― ― ― ― ― ― ― ― ―
E15: ㅇ 자본적지출 | G15: ― ― ― ― ― ― ― ― ― ― ― ― ― ― ― ― ― ― ― ― ― ― ― ― ― ― ―
D16: 6. 자금운영계획
E17: ㅇ 수입자금 | G17: ― ― ― ― ― ― ― ― ― ― ― ― ― ― ― ― ― ― ― ― ― ― ― ― ― ― ―
E18: ㅇ 지출자금 | G18: ― ― ― ― ― ― ― ― ― ― ― ― ― ― ― ― ― ― ― ― ― ― ― ― ― ― ―
D19: < 별 첨 >
E20: ㅇ 계속비조서 | G20: ― ― ― ― ― ― ― ― ― ― ― ― ― ― ― ― ― ― ― ― ― ― ― ― ― ― ―
E21: ㅇ 이월비조서 | G21: ― ― ― ― ― ― ― ― ― ― ― ― ― ― ― ― ― ― ― ― ― ― ― ― ― ― ―
E22: ㅇ 외부자금 차입 및 상환조서 | H22: ― ― ― ― ― ― ― ― ― ― ― ― ― ― ― ― ― ― ― ― ― ―
E23: ㅇ 중요자산 취득 및 처분조서 | H23: ― ― ― ― ― ― ― ― ― ― ― ― ― ― ― ― ― ― ― ― ― ―

Sheet 사업운영계획(표지)
B16: 1. 사업운영계획

Sheet 1.사업운영계획(완료)
C1: 1. 사업운영계획
W2: (단위 : 천원) | AS2: (단위 : 천원)
B3: 구 분 | E3: 예산액 | F3: 식품 | G3: 의약 | H3: 나노 | I3: 천연 | J3: 해양 | K3: 한방 | L3: 방재 | M3: 행정 | N3: 전년도본예산액 | O3: 식품 | P3: 의약 | Q3: 나노 | R3: 천연 | S3: 해양 | T3: 한방 | U3: 방재 | V3: 행정 | W3: 증 감 | Y3: 구 분 | AA3: 예산액 | AB3: 식품 | AC3: 의약 | AD3: 나노 | AE3: 천연 | AF3: 해양 | AG3: 한방 | AH3: 방제 | AI3: 행정 | AJ3: 전년도본예산액 | AK3: 식품 | AL3: 의약 | AM3: 나노 | AN3: 천연 | AO3: 해양 | AP3: 한방 | AQ3: 방제 | AR3: 행정 | AS3: 증 감
B4: 수입 총계 | E4: =SUM(E5,E24,E21) -> 5340000000 | F4: =SUM(F5,F24,F21) -> 99.892515 | G4: =SUM(G5,G24,G21) -> 38867552000 | H4: =SUM(H5,H24,H21) -> 99.768979 | I4: =SUM(I5,I24,I21) -> 2953848000 | J4: =SUM(J5,J24,J21) -> #DIV/0! | K4: =SUM(K5,K24,K21) -> #REF! | L4: =SUM(L5,L24,L21) -> #REF! | ... W4: =SUM(W5,W24,W21) -> 44426000 | Y4: 지출 총계 | AA4: =AA5+AA27+AA32 -> 32072175407 | AB4: =AB5+AB27+AB32 -> 0 | AC4: =AC5+AC27+AC32 -> 0 | AD4: =AD5+AD27+AD32 -> 0 | AE4: =AE5+AE27+AE32 -> 0 | AF4: =AF5+AF27+AF32 -> 0 | AG4: =AG5+AG27+AG32 -> 0 | AH4: =AH5+AH27+AH32 -> 0 | ... AR4: =AR5+AR27+AR32 -> 0 | AS4: =AS5+AS27+AS32-1000 -> -9794225145
B5: 영 업 수 익 | C5: 영업수입 계 | E5: =SUM(E6,E9,E12,E16,E20) -> 1340000000 | F5: =SUM(F6,F9,F12,F16) -> 55.395799 | G5: =SUM(G6,G9,G12,G16) -> 22463272000 | H5: =SUM(H6,H9,H12,H16) -> 57.660892 | I5: =SUM(I6,I9,I12,I16) -> 728955000 | J5: =SUM(J6,J9,J12,J16) -> #DIV/0! | K5: =SUM(K6,K9,K12,K16) -> #REF! | L5: =SUM(L6,L9,L12,L16) -> #REF! | M5: =SUM(M6,M9,M12,M16) -> 0 | N5: =SUM(N6,N9,N12,N16,N20) -> 1885574000 | O5: =SUM(O6,O9,O12,O16) -> 0 | P5: =SUM(P6,P9,P12,P16) -> 0 | Q5: =SUM(Q6,Q9,Q12,Q16) -> 0 | R5: =SUM(R6,R9,R12,R16) -> 0 | S5: =SUM(S6,S9,S12,S16) -> 0 | T5: =SUM(T6,T9,T12,T16) -> 0 | U5: =SUM(U6,U9,U12,U16) -> 0 | V5: =SUM(V6,V9,V12,V16) -> 0 | W5: =SUM(W6,W9,W12,W16,W20) -> -545574000 | Y5: 사업비용 총계 | AA5: =AA6+AA26 -> 26426013407 | AB5: =AB6+AB26 -> 0 | AC5: =AC6+AC26 -> 0 | AD5: =AD6+AD26 -> 0 | AE5: =AE6+AE26 -> 0 | AF5: =AF6+AF26 -> 0 | AG5: =AG6+AG26 -> 0 | AH5: =AH6+AH26 -> 0 | ... AS5: =AS6+AS26 -> -3434684145
C6: 1.관리사업 | D6: 계 | E6: =SUM(E7:E8) -> 940000000 | F6: =SUM(F7:F8) -> 21.57716 | G6: =SUM(G7:G8) -> 8425280000 | H6: =SUM(H7:H8) -> 21.626821 | I6: =SUM(I7:I8) -> 608300000 | J6: =SUM(J7:J8) -> 7.2199381 | K6: =SUM(K7:K8) -> 0 | L6: =SUM(L7:L8) -> 0 | ... V6: =SUM(V7:V8) -> 0 | W6: =E6-N6 -> -110000000 | Y6: 영업비용 | Z6: 계 | AA6: =SUM(AA7:AA25) -> 26426013407 | AB6: =SUM(AB7:AB25) -> 0 | AC6: =SUM(AC7:AC25) -> 0 | AD6: =SUM(AD7:AD25) -> 0 | AE6: =SUM(AE7:AE25) -> 0 | AF6: =SUM(AF7:AF25) -> 0 | AG6: =SUM(AG7:AG25) -> 0 | AH6: =SUM(AH7:AH25) -> 0 | ... AS6: =SUM(AS7:AS25) -> -3427184145
D7: 1)관리사업수익 | E7: ='3-4. 수입예산 성질별 총괄표(완료)'!F8 -> 940000000 | F7: ='[1]3-4. 수입예산 성질별 총괄표'!G11 -> 21.57716 | G7: ='[1]3-4. 수입예산 성질별 총괄표'!H11 -> 8425280000 | H7: ='[1]3-4. 수입예산 성질별 총괄표'!I11 -> 21.626821 | I7: ='[1]3-4. 수입예산 성질별 총괄표'!J11 -> 608300000 | J7: ='[1]3-4. 수입예산 성질별 총괄표'!K11 -> 7.2199381 | K7: ='[1]3-4. 수입예산 성질별 총괄표'!L11 -> 0 | L7: ='[1]3-4. 수입예산 성질별 총괄표'!M11 -> 0 | M7: ='[1]3-4. 수입예산 성질별 총괄표'!N11 -> 0 | N7: ='3-4. 수입예산 성질별 총괄표(완료)'!H8 -> 1050000000 | W7: =E7-N7 -> -110000000 | Z7: 인건비 | AA7: ='3-5.지출예산 성질별총괄표(완료)'!F8 -> 10495421913 | AJ7: ='3-5.지출예산 성질별총괄표(완료)'!H8 -> 12222887892 | AS7: =AA7-AJ7 -> -1727465979
D8: 2)관리사업부대수익 | Z8: 퇴직급여 | AA8: ='3-5.지출예산 성질별총괄표(완료)'!F11 -> 1036569000 | AJ8: ='3-5.지출예산 성질별총괄표(완료)'!H11 -> 853779000 | AS8: =AA8-AJ8 -> 182790000
C9: 2.대행사업 | D9: 계 | E9: =SUM(E10:E11) -> 300000000 | F9: =SUM(F10:F11) -> 17.066304 | G9: =SUM(G10:G11) -> 8076283000 | H9: =SUM(H10:H11) -> 20.730982 | I9: =SUM(I10:I11) -> -931236000 | J9: =SUM(J10:J11) -> -14.756345 | K9: =SUM(K10:K11) -> 0 | L9: =SUM(L10:L11) -> 7145047000 | ... V9: =SUM(V10:V11) -> 0 | W9: =E9-N9 -> -435574000 | Z9: 일반운영비 | AA9: ='3-5.지출예산 성질별총괄표(완료)'!F12 -> 2809940000 | AJ9: ='3-5.지출예산 성질별총괄표(완료)'!H12 -> 3088183000 | AS9: =AA9-AJ9 -> -278243000
D10: 1)직접관리비수익 | E10: ='3-4. 수입예산 성질별 총괄표(완료)'!F12 -> 265000000 | F10: ='[1]3-4. 수입예산 성질별 총괄표'!G15 -> 15.731427 | G10: ='[1]3-4. 수입예산 성질별 총괄표'!H15 -> 7502861000 | H10: ='[1]3-4. 수입예산 성질별 총괄표'!I15 -> 19.259067 | I10: ='[1]3-4. 수입예산 성질별 총괄표'!J15 -> -916679000 | J10: ='[1]3-4. 수입예산 성질별 총괄표'!K15 -> -12.217726 | K10: ='[1]3-4. 수입예산 성질별 총괄표'!L15 -> 0 | L10: ='[1]3-4. 수입예산 성질별 총괄표'!M15 -> 6586182000 | M10: ='[1]3-4. 수입예산 성질별 총괄표'!N15 -> 0 | N10: ='3-4. 수입예산 성질별 총괄표(완료)'!H12 -> 569938000 | W10: =E10-N10 -> -304938000 | Z10: 여비 | AA10: ='3-5.지출예산 성질별총괄표(완료)'!F19 -> 520360000 | AJ10: ='3-5.지출예산 성질별총괄표(완료)'!H19 -> 440364000 | AS10: =AA10-AJ10 -> 79996000
D11: 2)간접관리비수익 | E11: ='3-4. 수입예산 성질별 총괄표(완료)'!F13 -> 35000000 | F11: ='[1]3-4. 수입예산 성질별 총괄표'!G16 -> 1.3348771 | G11: ='[1]3-4. 수입예산 성질별 총괄표'!H16 -> 573422000 | H11: ='[1]3-4. 수입예산 성질별 총괄표'!I16 -> 1.4719149 | I11: ='[1]3-4. 수입예산 성질별 총괄표'!J16 -> -14557000 | J11: ='[1]3-4. 수입예산 성질별 총괄표'!K16 -> -2.538619 | K11: ='[1]3-4. 수입예산 성질별 총괄표'!L16 -> 0 | L11: ='[1]3-4. 수입예산 성질별 총괄표'!M16 -> 558865000 | M11: ='[1]3-4. 수입예산 성질별 총괄표'!N16 -> 0 | N11: ='3-4. 수입예산 성질별 총괄표(완료)'!H13 -> 165636000 | W11: =E11-N11 -> -130636000 | Z11: 업무추진비 | AA11: ='3-5.지출예산 성질별총괄표(완료)'!F22 -> 71100000 | AJ11: ='3-5.지출예산 성질별총괄표(완료)'!H22 -> 72600000 | AS11: =AA11-AJ11 -> -1500000
C12: 3.보조금수익 | D12: 계 | E12: =SUM(E13:E15) -> 0 | F12: =SUM(F14:F15) -> 1.7914127 | G12: =SUM(G14:G15) -> 574000000 | H12: =SUM(H14:H15) -> 1.4733985 | I12: =SUM(I14:I15) -> 176000000 | J12: =SUM(J14:J15) -> #DIV/0! | K12: =SUM(K14:K15) -> #REF! | L12: =SUM(L14:L15) -> #REF! | M12: =SUM(M14:M15) -> 0 | N12: =SUM(N13:N15) -> 0 | W12: =E12-N12 -> 0 | Z12: 직무수행경비 | AA12: ='3-5.지출예산 성질별총괄표(완료)'!F24 -> 78480000 | AJ12: ='3-5.지출예산 성질별총괄표(완료)'!H24 -> 86160000 | AS12: =AA12-AJ12 -> -7680000
D13: 1)국비보조금수익 | Z13: 재료비 | AA13: ='3-5.지출예산 성질별총괄표(완료)'!F27 -> 435450000 | AJ13: ='3-5.지출예산 성질별총괄표(완료)'!H27 -> 639650000 | AS13: =AA13-AJ13 -> -204200000
D14: 2)자치단체보조금수익 | E14: ='3-4. 수입예산 성질별 총괄표(완료)'!F16 -> 0 | F14: ='[1]3-4. 수입예산 성질별 총괄표'!G19 -> 1.7914127 | G14: ='[1]3-4. 수입예산 성질별 총괄표'!H19 -> 574000000 | H14: ='[1]3-4. 수입예산 성질별 총괄표'!I19 -> 1.4733985 | I14: ='[1]3-4. 수입예산 성질별 총괄표'!J19 -> 176000000 | J14: ='[1]3-4. 수입예산 성질별 총괄표'!K19 -> 30.662021 | K14: ='[1]3-4. 수입예산 성질별 총괄표'!#REF! -> #REF! | L14: ='[1]3-4. 수입예산 성질별 총괄표'!#REF! -> #REF! | M14: ='[1]3-4. 수입예산 성질별 총괄표'!L19 -> 0 | N14: ='3-4. 수입예산 성질별 총괄표(완료)'!H16 -> 0 | W14: =E14-N14 -> 0 | Z14: 연구개발비 | AA14: ='3-5.지출예산 성질별총괄표(완료)'!F29 -> 964619000 | AJ14: ='3-5.지출예산 성질별총괄표(완료)'!H29 -> 1398835000 | AS14: =AA14-AJ14 -> -434216000
D15: 2)기타보조금수익 | E15: ='3-4. 수입예산 성질별 총괄표(완료)'!F17 -> 0 | F15: ='[1]3-4. 수입예산 성질별 총괄표'!G20 -> 0 | G15: ='[1]3-4. 수입예산 성질별 총괄표'!H20 -> 0 | H15: ='[1]3-4. 수입예산 성질별 총괄표'!I20 -> 0 | I15: ='[1]3-4. 수입예산 성질별 총괄표'!J20 -> 0 | J15: ='[1]3-4. 수입예산 성질별 총괄표'!K20 -> #DIV/0! | K15: ='[1]3-4. 수입예산 성질별 총괄표'!#REF! -> #REF! | L15: ='[1]3-4. 수입예산 성질별 총괄표'!#REF! -> #REF! | M15: ='[1]3-4. 수입예산 성질별 총괄표'!L20 -> 0 | N15: ='3-4. 수입예산 성질별 총괄표(완료)'!H17 -> 0 | W15: =E15-N15 -> 0 | Z15: 교육훈련비 | AA15: ='3-5.지출예산 성질별총괄표(완료)'!F33 -> 176250000 | AJ15: ='3-5.지출예산 성질별총괄표(완료)'!H33 -> 342416000 | AS15: =AA15-AJ15 -> -166166000
C16: 4.출연금수익 | D16: 계 | E16: =SUM(E17:E19) -> 100000000 | F16: =SUM(F17:F19) -> 14.960923 | G16: =SUM(G17:G19) -> 5387709000 | H16: =SUM(H17:H19) -> 13.829691 | I16: =SUM(I17:I19) -> 875891000 | J16: =SUM(J17:J19) -> 16.257207 | K16: =SUM(K17:K19) -> #REF! | L16: =SUM(L17:L19) -> #REF! | ... W16: =SUM(W17:W19) -> 0 | Z16: 수선유지교체비 | AA16: ='3-5.지출예산 성질별총괄표(완료)'!F34 -> 1307423494 | AJ16: ='3-5.지출예산 성질별총괄표(완료)'!H34 -> 1127200000 | AS16: =AA16-AJ16 -> 180223494
D17: 1)정부출연금수익 | Z17: 동력비 | AA17: ='3-5.지출예산 성질별총괄표(완료)'!F36 -> 3127162000 | AJ17: ='3-5.지출예산 성질별총괄표(완료)'!H36 -> 3091800000 | AS17: =AA17-AJ17 -> 35362000
D18: 2)자치단체출연금수익 | E18: ='3-4. 수입예산 성질별 총괄표(완료)'!F21 -> 100000000 | F18: ='[1]3-4. 수입예산 성질별 총괄표'!G24 -> 14.960923 | G18: ='[1]3-4. 수입예산 성질별 총괄표'!H24 -> 5387709000 | H18: ='[1]3-4. 수입예산 성질별 총괄표'!I24 -> 13.829691 | I18: ='[1]3-4. 수입예산 성질별 총괄표'!J24 -> 875891000 | J18: ='[1]3-4. 수입예산 성질별 총괄표'!K24 -> 16.257207 | K18: ='[1]3-4. 수입예산 성질별 총괄표'!#REF! -> #REF! | L18: ='[1]3-4. 수입예산 성질별 총괄표'!#REF! -> #REF! | M18: ='[1]3-4. 수입예산 성질별 총괄표'!L24 -> 0 | N18: ='3-4. 수입예산 성질별 총괄표(완료)'!H21 -> 100000000 | W18: =E18-N18 -> 0 | Z18: 관서업무비 | AA18: ='3-5.지출예산 성질별총괄표(완료)'!F37 -> 43140000 | AJ18: ='3-5.지출예산 성질별총괄표(완료)'!H37 -> 44630000 | AS18: =AA18-AJ18 -> -1490000
D19: 3)기타출연금수익 | Z19: 평가급 | AA19: ='3-5.지출예산 성질별총괄표(완료)'!F40 -> 1097405000 | AJ19: ='3-5.지출예산 성질별총괄표(완료)'!H40 -> 1176999500 | AS19: =AA19-AJ19 -> -79594500
C20: 5.연구용역수익 | D20: 1)연구용역수익 | E20: ='3-4. 수입예산 성질별 총괄표(완료)'!F26 -> 0 | N20: ='3-4. 수입예산 성질별 총괄표(완료)'!H26 -> 0 | W20: =E20-N20 -> 0 | Z20: 위탁관리비 | AA20: ='3-5.지출예산 성질별총괄표(완료)'!F41 -> 677656000 | AJ20: ='3-5.지출예산 성질별총괄표(완료)'!H41 -> 1058334000 | AS20: =AA20-AJ20 -> -380678000
B21: 영업외 수익 | C21: 영업외수입 계 | E21: =SUM(E22:E23) -> 0 | F21: =SUM(F22:F23) -> 2.6497549 | G21: =SUM(G22:G23) -> 225600000 | H21: =SUM(H22:H23) -> 0.57909183 | I21: =SUM(I22:I23) -> 883757000 | J21: =SUM(J22:J23) -> 571.69494 | K21: =SUM(K22:K23) -> #REF! | L21: =SUM(L22:L23) -> #REF! | ... W21: =SUM(W22:W23) -> 0 | Z21: 일반보상금 | AA21: ='3-5.지출예산 성질별총괄표(완료)'!F42 -> 9680000 | AJ21: ='3-5.지출예산 성질별총괄표(완료)'!H42 -> 0 | AS21: =AA21-AJ21 -> 9680000
C22: 5.이자수익 | D22: 예금이자수익 | E22: ='3-4. 수입예산 성질별 총괄표(완료)'!F29 -> 0 | F22: ='[1]3-4. 수입예산 성질별 총괄표'!G32 -> 0.19538341 | G22: ='[1]3-4. 수입예산 성질별 총괄표'!H32 -> 35300000 | H22: ='[1]3-4. 수입예산 성질별 총괄표'!I32 -> 0.090611443 | I22: ='[1]3-4. 수입예산 성질별 총괄표'!J32 -> 46500000 | J22: ='[1]3-4. 수입예산 성질별 총괄표'!K32 -> 131.72805 | K22: ='[1]3-4. 수입예산 성질별 총괄표'!#REF! -> #REF! | L22: ='[1]3-4. 수입예산 성질별 총괄표'!#REF! -> #REF! | M22: ='[1]3-4. 수입예산 성질별 총괄표'!L32 -> 0 | N22: ='3-4. 수입예산 성질별 총괄표(완료)'!H29 -> 0 | W22: =E22-N22 -> 0 | Z22: 포상금 | AA22: ='3-5.지출예산 성질별총괄표(완료)'!F45 -> 129250000 | AJ22: ='3-5.지출예산 성질별총괄표(완료)'!H45 -> 90000000 | AS22: =AA22-AJ22 -> 39250000
C23: 6.기타영업외수익 | D23: 기타영업외수익 | E23: ='3-4. 수입예산 성질별 총괄표(완료)'!F31 -> 0 | F23: ='[1]3-4. 수입예산 성질별 총괄표'!G37 -> 2.4543715 | G23: ='[1]3-4. 수입예산 성질별 총괄표'!H37 -> 190300000 | H23: ='[1]3-4. 수입예산 성질별 총괄표'!I37 -> 0.48848039 | I23: ='[1]3-4. 수입예산 성질별 총괄표'!J37 -> 837257000 | J23: ='[1]3-4. 수입예산 성질별 총괄표'!K37 -> 439.96689 | K23: ='[1]3-4. 수입예산 성질별 총괄표'!#REF! -> #REF! | L23: ='[1]3-4. 수입예산 성질별 총괄표'!#REF! -> #REF! | M23: ='[1]3-4. 수입예산 성질별 총괄표'!L37 -> 0 | N23: ='3-4. 수입예산 성질별 총괄표(완료)'!H31 -> 0 | O23: =SUM(#REF!) -> #REF! | P23: =SUM(#REF!) -> #REF! | Q23: =SUM(#REF!) -> #REF! | R23: =SUM(#REF!) -> #REF! | S23: =SUM(#REF!) -> #REF! | T23: =SUM(#REF!) -> #REF! | U23: =SUM(#REF!) -> #REF! | V23: =SUM(#REF!) -> #REF! | W23: =E23-N23 -> 0 | Z23: 연금부담금 등 | AA23: ='3-5.지출예산 성질별총괄표(완료)'!F47 -> 867800000 | AJ23: ='3-5.지출예산 성질별총괄표(완료)'!H47 -> 1041463160 | AS23: =AA23-AJ23 -> -173663160
B24: 자 본 적 수 입 | C24: 7.자본잉여금 | D24: 계 | E24: =SUM(E25:E28) -> 4000000000 | F24: =SUM(F25:F28) -> 41.846961 | G24: =SUM(G25:G28) -> 16178680000 | H24: =SUM(H25:H28) -> 41.528995 | I24: =SUM(I25:I28) -> 1341136000 | J24: =SUM(J25:J28) -> -22.714329 | K24: =SUM(K25:K28) -> #REF! | L24: =SUM(L25:L28) -> #REF! | ... V24: =SUM(V25:V28) -> 0 | W24: =E24-N24 -> 590000000 | Z24: 자치단체등이전 | AA24: ='3-5.지출예산 성질별총괄표(완료)'!F49 -> 780000000 | AJ24: ='3-5.지출예산 성질별총괄표(완료)'!H49 -> 1273000000 | AS24: =AA24-AJ24 -> -493000000
D25: 1)국고보조금 | Z25: 민간사업지원금 | AA25: ='3-5.지출예산 성질별총괄표(완료)'!F51 -> 1798307000 | AJ25: ='3-5.지출예산 성질별총괄표(완료)'!H51 -> 1804896000 | AS25: =AA25-AJ25 -> -6589000
D26: 2)자치단체보조금 | E26: ='3-4. 수입예산 성질별 총괄표(완료)'!F47 -> 0 | F26: ='[1]3-4. 수입예산 성질별 총괄표'!G54 -> 11.942751 | G26: ='[1]3-4. 수입예산 성질별 총괄표'!H54 -> 0 | H26: ='[1]3-4. 수입예산 성질별 총괄표'!I54 -> 0 | I26: ='[1]3-4. 수입예산 성질별 총괄표'!J54 -> 5000000000 | J26: ='[1]3-4. 수입예산 성질별 총괄표'!K54 -> 0 | K26: ='[1]3-4. 수입예산 성질별 총괄표'!#REF! -> #REF! | L26: ='[1]3-4. 수입예산 성질별 총괄표'!#REF! -> #REF! | M26: ='[1]3-4. 수입예산 성질별 총괄표'!L54 -> 0 | N26: ='3-4. 수입예산 성질별 총괄표(완료)'!H47 -> 0 | W26: =E26-N26 -> 0 | Y26: 영업외비용 | Z26: 반환금 | AA26: ='3-5.지출예산 성질별총괄표(완료)'!F55 -> 0 | AJ26: ='3-5.지출예산 성질별총괄표(완료)'!H55 -> 7500000 | AS26: =AA26-AJ26 -> -7500000
D27: 3)수탁자산보조금 | E27: ='3-4. 수입예산 성질별 총괄표(완료)'!F49 -> 4000000000 | F27: ='[1]3-4. 수입예산 성질별 총괄표'!G56 -> 18.109869 | G27: ='[1]3-4. 수입예산 성질별 총괄표'!H56 -> 11812810000 | H27: ='[1]3-4. 수입예산 성질별 총괄표'!I56 -> 30.322259 | I27: ='[1]3-4. 수입예산 성질별 총괄표'!J56 -> -4230860000 | J27: ='[1]3-4. 수입예산 성질별 총괄표'!K56 -> -35.815864 | K27: ='[1]3-4. 수입예산 성질별 총괄표'!#REF! -> #REF! | L27: ='[1]3-4. 수입예산 성질별 총괄표'!#REF! -> #REF! | M27: ='[1]3-4. 수입예산 성질별 총괄표'!L56 -> 0 | N27: ='3-4. 수입예산 성질별 총괄표(완료)'!H49 -> 3410000000 | W27: =E27-N27 -> 590000000 | Y27: 자본적지출 | Z27: 계 | AA27: =SUM(AA28:AA31) -> 5646162000 | AB27: =SUM(AB28:AB31) -> 0 | AC27: =SUM(AC28:AC31) -> 0 | AD27: =SUM(AD28:AD31) -> 0 | AE27: =SUM(AE28:AE31) -> 0 | AF27: =SUM(AF28:AF31) -> 0 | AG27: =SUM(AG28:AG31) -> 0 | AH27: =SUM(AH28:AH31) -> 0 | ... AS27: =SUM(AS28:AS31) -> -5955388000
D28: 보통재산(운영재산) | E28: ='3-4. 수입예산 성질별 총괄표(완료)'!F52 -> 0 | F28: ='[1]3-4. 수입예산 성질별 총괄표'!G59 -> 11.794341 | G28: ='[1]3-4. 수입예산 성질별 총괄표'!H59 -> 4365870000 | H28: ='[1]3-4. 수입예산 성질별 총괄표'!I59 -> 11.206736 | I28: ='[1]3-4. 수입예산 성질별 총괄표'!J59 -> 571996000 | J28: ='[1]3-4. 수입예산 성질별 총괄표'!K59 -> 13.101535 | K28: ='[1]3-4. 수입예산 성질별 총괄표'!#REF! -> #REF! | L28: ='[1]3-4. 수입예산 성질별 총괄표'!#REF! -> #REF! | M28: ='[1]3-4. 수입예산 성질별 총괄표'!L59 -> 0 | N28: ='3-4. 수입예산 성질별 총괄표(완료)'!H52 -> 0 | W28: =E28-N28 -> 0 | Z28: 시설비 및 부대비 | AA28: ='3-5.지출예산 성질별총괄표(완료)'!F61 -> 3129212000 | AJ28: ='3-5.지출예산 성질별총괄표(완료)'!H61 -> 6105000000 | AS28: =AA28-AJ28 -> -2975788000
Z29: 자산취득비 | AA29: ='3-5.지출예산 성질별총괄표(완료)'!F66 -> 2359450000 | AJ29: ='3-5.지출예산 성질별총괄표(완료)'!H66 -> 5397550000 | AS29: =AA29-AJ29 -> -3038100000
B30: 보통재산 (세출미반영) | D30: 보통재산 재원 및 용도 | E30: 2024년 말 기초보유액 | N30: 2025년 증감액 (예정) | O30: 의약 | P30: 나노 | Q30: 천연 | R30: 해양 | S30: 한방 | T30: 방제 | U30: 행정 | V30: 증 감 | W30: 2025년 기말 보유예상액 | Z30: 기타자산취득 | AA30: ='3-5.지출예산 성질별총괄표(완료)'!F68 -> 157500000 | AJ30: ='3-5.지출예산 성질별총괄표(완료)'!H68 -> 99000000 | AS30: =AA30-AJ30 -> 58500000
O31: 0 | P31: 0 | Q31: 0 | R31: 0 | S31: 0 | T31: 0 | U31: 0 | V31: 0 | Z31: 기타자본적지출 | AS31: =AA31-AJ31 -> 0
D32: 1. 재원 - 기반구축 부가세 - 흑자 시 관리사업수익 3% 2. 용도 - 기관 사업개편 등 재투자 - 인건비 유보자금(3개월) | E32: 4800000000 | F32: 0 | G32: 0 | H32: 0 | I32: 0 | J32: 0 | K32: 0 | L32: 0 | M32: 0 | N32: 312962400 | O32: 0 | P32: 0 | Q32: 0 | R32: 0 | S32: 0 | T32: 0 | U32: 0 | V32: 0 | W32: 5112962400 | Y32: 예비비 | Z32: 예비비 | AA32: ='3-5.지출예산 성질별총괄표(완료)'!F75 -> 0 | AJ32: ='3-5.지출예산 성질별총괄표(완료)'!H75 -> 404152000 | AK32: ='[1]3-5.지출예산 성질별총괄표'!P94 -> 0 | AL32: ='[1]3-5.지출예산 성질별총괄표'!Q94 -> 0 | AM32: ='[1]3-5.지출예산 성질별총괄표'!R94 -> 0 | AN32: ='[1]3-5.지출예산 성질별총괄표'!S94 -> 0 | AO32: ='[1]3-5.지출예산 성질별총괄표'!T94 -> 0 | AP32: ='[1]3-5.지출예산 성질별총괄표'!U94 -> 0 | AQ32: ='[1]3-5.지출예산 성질별총괄표'!V94 -> 0 | AR32: ='[1]3-5.지출예산 성질별총괄표'!W94 -> 0 | AS32: =AA32-AJ32 -> -404152000
Y33: 인력관리 계획 | Z33: 계 | AA33: =AA34+AA35 -> 204 | AB33: =AB34+AB35 -> 0 | AC33: =AC34+AC35 -> 0 | AD33: =AD34+AD35 -> 0 | AE33: =AE34+AE35 -> 0 | AF33: =AF34+AF35 -> 0 | AG33: =AG34+AG35 -> 0 | AH33: =AH34+AH35 -> 0 | ... AS33: =AS34+AS35 -> -6
Z34: 정규직(정원) | AA34: 183 | AJ34: 183 | AS34: =AA34-AJ34 -> 0
Z35: 위촉직(현원) | AA35: 21 | AJ35: 27 | AS35: =AA35-AJ35 -> -6
F51: =SUM(F52:F59) -> 0 | G51: =SUM(G52:G59) -> 0 | H51: =SUM(H52:H59) -> 0 | I51: =SUM(I52:I59) -> 0

Sheet 예산총칙(표지)
B16: 2. 예산총칙

Sheet 2.예산총칙(완료)
B1: 2. 예산총칙
B2: 제1조 (총칙) 2025년도 전남바이오진흥원의 예산은 다음과 같이 정한다. | G2: 제5조(계속비) 계속비의 총액과 연할액은 다음과 같이 정한다.
G3: (그 세부내역은 별첨 "계속비조서"와 같다.)
B4: 제2조 (업무의 예정량) 업무의 예정량은 다음과 같다. | L4: (단위 : 천원)
B5: ㅇ 관리사업(장비, 임대, 분석, 기술료 등) | D5: ='3-4. 수입예산 성질별 총괄표(완료)'!F8 -> 940000000 | E5: 천원 | G5: 관 | H5: 항 | I5: 사업명 | J5: 총액 | K5: 년도 | L5: 연할액
B6: ㅇ 대행&보조금사업(기반구축사업 포함) | D6: ='3-4. 수입예산 성질별 총괄표(완료)'!F11+'3-4. 수입예산 성질별 총괄표(완료)'!F14+'3-4. 수입예산 성질별 총괄표(완료)'!F45+'3-4. 수입예산 성질별 총괄표(완료)'!F48 -> 4300000000 | E6: 천원 | G6: 영업비용 | H6: 일반관리비 | I6: 전남생물산업지원사업 성과활용사업 | J6: 271888000 | K6: ~ 2023년 | L6: ='별첨7-2.계속비설명서(완료)'!G5 -> 234181680
B7: ㅇ 전라남도 바이오 진흥을 위한 자체사업 | D7: ='3-4. 수입예산 성질별 총괄표(완료)'!F5-'2.예산총칙(완료)'!D5-'2.예산총칙(완료)'!D6 -> 100000000 | E7: 천원 | K7: 2024년 | L7: ='별첨7-2.계속비설명서(완료)'!K5 -> 30481599
K8: 2025년 | L8: ='별첨7-2.계속비설명서(완료)'!M5 -> 7224721
B9: 제3조(수익적사업 및 지출) 수익적사업 및 지출의 예정액은 다음과 같다. | K9: 2026년 이후 | L9: 종료
E10: (단위 : 천원)
B11: 사업수입 | D11: 사업비용
B12: 과 목 | C12: 금 액 | D12: 과 목 | E12: 금 액 | G12: 제6조(일시차입금) 일시차입금 한도액은 0원으로 정한다.
B13: 합 계 | C13: =SUM(C14:C15) -> 1340000000 | D13: 합 계 | E13: =SUM(E14,E15,E16) -> 26426013407
B14: 제1항 영업수익 | C14: ='3-1.예산총괄표(완료)'!C5 -> 1340000000 | D14: 제1항 영업비용 | E14: ='3-1.예산총괄표(완료)'!C17 -> 26426013407 | G14: 제7조(예산전용금지과목) 다음에 게기하는 과목의 경비는 이사회의 의결을 거치지 않고는
B15: 제2항 영업외 수익 | C15: ='3-1.예산총괄표(완료)'!C6 -> 0 | D15: 제2항 영업외비용 | G15: 그 경비를 전용할 수 없다.
D16: 예비비 | G16: (1) 인건비(세목 간, 인건비 관련 비목간 전용 가능) | J16: ='3-5.지출예산 성질별총괄표(완료)'!F8 -> 10495421913 | K16: 천원
G17: (2) 업무추진비(타 비목으로부터의 전용금지) | J17: ='3-5.지출예산 성질별총괄표(완료)'!F22 -> 71100000 | K17: 천원
B18: 제4조(자본적수입 및 지출) 자본적수입 및 지출의 예정액은 다음과 같이 정한다. | G18: (3) 시설비 및 부대비 | J18: ='3-5.지출예산 성질별총괄표(완료)'!F61 -> 3129212000 | K18: 천원
E19: (단위 : 천원)
B20: 자본적수입 | D20: 자본적지출 | G20: 제8조(대행사업 경비) 대행사업을 위하여 국,도,시군비로 이 출연기관에 보조하는 금액은
B21: 과 목 | C21: 금 액 | D21: 과 목 | E21: 금 액 | G21: ='3-4. 수입예산 성질별 총괄표(완료)'!F16+'3-4. 수입예산 성질별 총괄표(완료)'!F47+'3-4. 수입예산 성질별 총괄표(완료)'!F49 -> 4000000000 | H21: 천원이다
B22: 합 계 | C22: =SUM(C23:C29) -> 4000000000 | D22: 합 계 | E22: =SUM(E23:E29) -> 5646162000
B23: 제1항 투자자산 | D23: 제1항 투자자산 | G23: 제9조(중요자산취득 및 처분) 중요자산의 취득 및 처분은 다음과 같이 한다.
B24: 제2항 고정자산매각수입 | D24: 제2항 유형자산 | E24: ='3-1.예산총괄표(완료)'!E25 -> 5488662000 | G24: (그 세부내역은 별첨 "중요자산취득 및 처분조서"와 같다.)
B25: 제3항 고정부채수입 | D25: 제3항 기타(무형)자산 | E25: ='3-1.예산총괄표(완료)'!E26 -> 155500000 | L25: (단위 : 천원)
B26: 제4항 자본금 | D26: 제4항 유동부채상환금 | E26: ='3-1.예산총괄표(완료)'!E27 -> 2000000 | G26: 구 분 | H26: 종 류 | I26: 명 칭 | K26: 수 량 | L26: 금 액
B27: 제5항 자본잉여금수입 | C27: ='3-1.예산총괄표(완료)'!E12 -> 4000000000 | D27: 제5항 고정부채상환금 | G27: 1. 취득자산 | H27: 건물 | I27: HMR 실증실용화 지원센터 건물 외 | K27: 7 | L27: 5094383000
B28: 제6항 기타자본잉여금수입 | D28: 제6항 기타자본적지출 | H28: 기계장치 | I28: HMR 실증실용화 지원센터, 초임계 장치 외 | K28: 19 | L28: 7678218000
B29: 제7항 유보자금 | D29: 제7항 예비비 | H29: 소프트웨어 | I29: 한컴-웹기안기 | K29: 1 | L29: 60000000
H30: 차량운반구 | I30: 생산지원 지게차 | K30: 1 | L30: 50000000
H31: 공구 비품 | I31: 실험실 책상 등 비품 | K31: 42 | L31: 176000000
K32: =SUM(K27:K31) -> 70 | L32: =SUM(L27:L31) -> 13058601000
K35: =SUM(K27:K31) -> 70 | L35: =SUM(L27:L31) -> 13058601000

Sheet 예산총괄표(표지)
B16: 3. 예산총괄표

Sheet 3-1.예산총괄표(완료)
B1: 3-1. 예산총괄표
G2: (단위 : 천원)
B3: 사 업 예 산 | D3: 자 본 예 산 | F3: 자 금 예 산
B4: 수 입 계 (A) | C4: =SUM(C5:C15) -> 1340000000 | D4: 수 입 계 (A') | E4: =SUM(E5:E14) -> 4000000000 | F4: 수 입 계 (A") | G4: =SUM(G5:G14) -> 5340000000
B5: 영업수익 | C5: ='3-2.사업예산총괄표(완료)'!D5 -> 1340000000 | F5: 영업수익 | G5: =C5 -> 1340000000
B6: 영업외수익 | C6: ='3-2.사업예산총괄표(완료)'!D14 -> 0 | F6: 영업외수익 | G6: =C6 -> 0
B7: 특별이익 | C7: ='3-2.사업예산총괄표(완료)'!D21 -> 0 | F7: 특별이익 | G7: =C7 -> 0
D8: 투자자산 | E8: ='3-3.자본예산총괄표(완료)'!D5 -> 0 | F8: 투자자산 | G8: =E8 -> 0
D9: 고정자산매각수입 | E9: ='3-3.자본예산총괄표(완료)'!D7 -> 0 | F9: 고정자산매각수입 | G9: =E9 -> 0
D10: 고정부채수입 | E10: ='3-3.자본예산총괄표(완료)'!D14 -> 0 | F10: 고정자산부채 | G10: =E10 -> 0
D11: 자본금 | E11: ='3-3.자본예산총괄표(완료)'!D22 -> 0 | F11: 자본금 | G11: =E11 -> 0
D12: 자본잉여금수입 | E12: ='3-3.자본예산총괄표(완료)'!D17 -> 4000000000 | F12: 자본잉여금수입 | G12: =E12 -> 4000000000
D13: 기타자본적수입 | E13: ='3-3.자본예산총괄표(완료)'!D24 -> 0 | F13: 기타자본적수입 | G13: =E13 -> 0
D14: 이월금 | E14: ='3-3.자본예산총괄표(완료)'!D26 -> 0 | F14: 이월금 | G14: =E14 -> 0
D15: [보통재산(운영재산)] | F15: [보통재산(운영재산)]
B16: 지 출 계 (B) | C16: =SUM(C17:C30) -> 26426013407 | D16: 지 출 계 (B') | E16: =SUM(E17:E30) -> 5646162000 | F16: 지 출 계 (B") | G16: =SUM(G17:G30) -> 32072175407
B17: 영업비용 | C17: ='3-2.사업예산총괄표(완료)'!G5 -> 26426013407 | F17: 영업비용 | G17: =C17 -> 26426013407
B18: 영업외비용 | C18: ='3-2.사업예산총괄표(완료)'!G14 -> 0 | F18: 영업외비용 | G18: =C18 -> 0
B19: 특별손실 | C19: ='3-2.사업예산총괄표(완료)'!G21 -> 0 | F19: 특별손실 | G19: =C19 -> 0
B20: 법인세등 | C20: ='3-2.사업예산총괄표(완료)'!G25 -> 0 | F20: 법인세등 | G20: =C20 -> 0
D24: 투자자산 | E24: ='3-3.자본예산총괄표(완료)'!G5 -> 0 | F24: 투자자산 | G24: =E24 -> 0
D25: 유형자산 | E25: ='3-3.자본예산총괄표(완료)'!G7 -> 5488662000 | F25: 유형자산 | G25: =E25 -> 5488662000
D26: 기타자산(무형)자산 | E26: ='3-3.자본예산총괄표(완료)'!G14 -> 155500000 | F26: 무형자산 | G26: =E26 -> 155500000
D27: 유동부채상환금 | E27: ='3-3.자본예산총괄표(완료)'!G24 -> 2000000 | F27: 유동부채상환금 | G27: =E27 -> 2000000
D28: 고정부채상환금 | E28: ='3-3.자본예산총괄표(완료)'!G22 -> 0 | F28: 고정부채상환금 | G28: =E28 -> 0
D29: 기타자본적지출 | E29: ='3-3.자본예산총괄표(완료)'!G27 -> 0 | F29: 기타자본적지출 | G29: =E29 -> 0
B30: 예비비 | C30: ='3-2.사업예산총괄표(완료)'!G27 -> 0 | D30: 예비비 | E30: ='3-3.자본예산총괄표(완료)'!G29 -> 0 | F30: 예비비 | G30: =E30 -> 0
B31: 차 인 (A-B) | C31: =C4-C16 -> -25086013407 | D31: 차 인 (A'-B') | E31: =E4-E16 -> -1646162000 | F31: 차 인 (A"-B") | G31: =G4-G16 -> -26732175407

Sheet 3-2.사업예산총괄표(완료)
B1: 3-2. 사업예산총괄표
G2: (단위 : 천원)
B3: 수 입 의 부 (A) | E3: 비 용 의 부 (B)
B4: 계 정 과 목 | D4: 금 액 | E4: 계 정 과 목 | G4: 금 액
B5: 영업수익 | C5: 계 | D5: =SUM(D6:D13) -> 1340000000 | E5: 영업비용 | F5: 계 | G5: =SUM(G6:G10) -> 26426013407
C6: 관리사업수익 | D6: ='3-4. 수입예산 성질별 총괄표(완료)'!F9 -> 940000000 | F6: 인건비, 퇴직급여 등 | G6: ='3-5.지출예산 성질별총괄표(완료)'!F8+'3-5.지출예산 성질별총괄표(완료)'!F11+'3-5.지출예산 성질별총괄표(완료)'!F26+'3-5.지출예산 성질별총괄표(완료)'!F47 -> 12421870913
C7: 대행사업수익 | D7: ='3-4. 수입예산 성질별 총괄표(완료)'!F11 -> 300000000 | F7: 경상경비 | G7: =I31 -> 10199180494
C8: 보조금수익 | D8: ='3-4. 수입예산 성질별 총괄표(완료)'!F14 -> 0 | F8: 평가급 | G8: ='3-5.지출예산 성질별총괄표(완료)'!F40 -> 1097405000
C9: 출연금수익 | D9: ='3-4. 수입예산 성질별 총괄표(완료)'!F18 -> 100000000 | F9: 포상금 | G9: ='3-5.지출예산 성질별총괄표(완료)'!F45 -> 129250000
C10: 연구용역수익 | D10: ='3-4. 수입예산 성질별 총괄표(완료)'!F25 -> 0 | F10: 민간사업지원 및 위탁금 | G10: ='3-5.지출예산 성질별총괄표(완료)'!F49+'3-5.지출예산 성질별총괄표(완료)'!F51 -> 2578307000
B14: 영업외수익 | C14: 계 | D14: =SUM(D15:D17) -> 0 | E14: 영업외비용 | F14: 계 | G14: =SUM(G15:G17) -> 0
C15: 이자수익 | D15: ='3-4. 수입예산 성질별 총괄표(완료)'!F28 -> 0 | F15: 기타영업외비용 | G15: ='3-5.지출예산 성질별총괄표(완료)'!F52 -> 0
C16: 기타영업외수익 | D16: ='3-4. 수입예산 성질별 총괄표(완료)'!F30 -> 0
B21: 특 별 이 익 | C21: 계 | D21: =SUM(D22:D23) -> 0 | E21: 특별손실 | F21: 계 | G21: =G22 -> 0
C22: 전기손익수정이익 | D22: 0 | F22: 기타특별손실 | G22: 0
C23: 기타특별이익 | D23: 0
E25: 법인세 | F25: 계 | G25: =G26 -> 0
F26: 법인세등 | G26: 0
E27: 예 비 비 | F27: 계 | G27: =G28 -> 0
F28: 예비비 | G28: ='3-5.지출예산 성질별총괄표(완료)'!F77 -> 0 | I28: ='3-5.지출예산 성질별총괄표(완료)'!F5 -> 32072175407
B29: 합 계 | D29: =D5+D14+D21+D25 -> 1340000000 | E29: 합 계 | G29: =G5+G14+G21+G25+G27 -> 26426013407 | I29: ='3-3.자본예산총괄표(완료)'!G30 -> 5646162000
B30: 차 액 (A-B) | G30: =D29-G29 -> -25086013407 | I30: =G6+G8+G9+G10 -> 16226832913
I31: =I28-SUM(I29:I30) -> 10199180494

Sheet 3-3.자본예산총괄표(완료)
B1: 3-3. 자본예산총괄표
G2: (단위 : 천원)
B3: 수 입 의 부 (A) | E3: 지 출 의 부 (B)
B4: 계 정 과 목 | D4: 금 액 | E4: 계 정 과 목 | G4: 금 액
B5: 투자자산수입 | C5: 계 | D5: =SUM(D6:D6) -> 0 | E5: 투자자산 | F5: 계 | G5: =SUM(G6:G6) -> 0
B7: 고정자산매각수입 | C7: 계 | D7: =SUM(D8:D13) -> 0 | E7: 유형자산 | F7: 계 | G7: =SUM(G8:G13) -> 5488662000
F8: 토지 | G8: 0
F9: 건물 | G9: ='3-5.지출예산 성질별총괄표(완료)'!F62 -> 3129212000
F10: 구축물 | G10: 0
F11: 기계장치 | G11: 2150450000
F12: 차량운반구 | G12: 50000000
F13: 공기구비품 | G13: 159000000
B14: 고정부채수입 | C14: 계 | D14: =SUM(D15:D15) -> 0 | E14: 무형자산 | F14: 계 | G14: =SUM(G15:G16) -> 155500000
F15: 특허권 등 | G15: ='3-5.지출예산 성질별총괄표(완료)'!F70 -> 95500000
F16: 정보화시스템취득비 | G16: ='3-5.지출예산 성질별총괄표(완료)'!F72 -> 60000000
B17: 자본잉여금수입 | C17: 계 | D17: =SUM(D18:D20) -> 4000000000 | E17: 재고자산 | F17: 계 | G17: 0
C18: 국고보조금 | D18: 0
C19: 자치단체보조금 | D19: ='3-4. 수입예산 성질별 총괄표(완료)'!F47 -> 0
C20: 수탁자산보조금수입 | D20: ='3-4. 수입예산 성질별 총괄표(완료)'!F49 -> 4000000000
B22: 자본금 | C22: 계 | D22: =SUM(D23:D23) -> 0 | E22: 고정부채상환금 | F22: 계 | G22: =SUM(G23:G23) -> 0
B24: 기타자본적수입 | C24: 계 | D24: =D25 -> 0 | E24: 유동부채상환 | F24: 계 | G24: =SUM(G25:G26) -> 2000000
F25: 선수금상환 | G25: ='3-5.지출예산 성질별총괄표(완료)'!F74 -> 2000000
B26: 이월금 | C26: 계 | D26: =SUM(D27:D28) -> 0
C27: 보통재산(운영재산) | D27: ='3-4. 수입예산 성질별 총괄표(완료)'!F52 -> 0 | E27: 기타자본적지출 | F27: 계 | G27: =SUM(G28) -> 0
F28: 기타자본적지출 | G28: ='[1]3-5.지출예산 성질별총괄표'!F88 -> 0
E29: 예 비 비 | G29: 0
B30: 합 계 | D30: =D5+D7+D14+D17+D22+D24+D26 -> 4000000000 | E30: 합 계 | G30: =G5+G7+G14+G17+G22+G24+G27+G29 -> 5646162000
B31: 차 액 (A-B) | G31: =D30-G30 -> -1646162000

Sheet 3-4. 수입예산 성질별 총괄표(완료)
B1: 3. 예산총괄표
B2: 3-4. 수입예산 성질별 총괄표 | K2: (단위 : 천원)
B3: 구 분 | F3: 본예산액 | G3: 구성비 | H3: 전년도 본예산액 | I3: 구성비 | J3: 증감 | K3: 증감률
B5: 총계 | F5: =SUM(F6,F32) -> 5340000000 | G5: =F5/$F$5*100 -> 100 | H5: =SUM(H6,H32) -> 5295574000 | I5: =H5/$H$5*100 -> 100 | J5: =F5-H5 -> 44426000 | K5: =J5/H5*100 -> 0.838927
B6: 600 사업수익 | F6: =SUM(F7,F27) -> 1340000000 | G6: =F6/$F$5*100 -> 25.093633 | H6: =SUM(H7,H27) -> 1885574000 | I6: =H6/$H$5*100 -> 35.606603 | J6: =F6-H6 -> -545574000 | K6: =J6/H6*100 -> -28.934107
C7: 610 영업수익 | F7: =SUM(F8,F11,F14,F23,F25,F18) -> 1340000000 | G7: =F7/$F$5*100 -> 25.093633 | H7: =SUM(H8,H11,H14,H18,H25) -> 1885574000 | I7: =H7/$H$5*100 -> 35.606603 | J7: =F7-H7 -> -545574000 | K7: =J7/H7*100 -> -28.934107
D8: 622 관리사업수익 | F8: =SUM(F9:F10) -> 940000000 | G8: =F8/$F$5*100 -> 17.602996 | H8: =SUM(H9:H10) -> 1050000000 | I8: =H8/$H$5*100 -> 19.827879 | J8: =F8-H8 -> -110000000 | K8: =J8/H8*100 -> -10.47619
E9: 622-01 관리사업수익 | F9: =수입예산!G10 -> 940000000 | G9: =F9/$F$5*100 -> 17.602996 | H9: =수입예산!H10 -> 1050000000 | I9: =H9/$H$5*100 -> 19.827879 | J9: =F9-H9 -> -110000000 | K9: =J9/H9*100 -> -10.47619
E10: 622-02 관리사업부대수익 | F10: 0 | G10: =F10/$F$5*100 -> 0 | H10: 0 | I10: =H10/$H$5*100 -> 0 | J10: =F10-H10 -> 0 | K10: =J10/H10*100 -> #DIV/0!
D11: 623 대행사업수익 | F11: =SUM(F12:F13) -> 300000000 | G11: =F11/$F$5*100 -> 5.6179775 | H11: =SUM(H12:H13) -> 735574000 | I11: =H11/$H$5*100 -> 13.890354 | J11: =F11-H11 -> -435574000 | K11: =J11/H11*100 -> -59.215524
E12: 623-01 직접관리비수익 | F12: =수입예산!G22 -> 265000000 | G12: =F12/$F$5*100 -> 4.9625468 | H12: =수입예산!H22 -> 569938000 | I12: =H12/$H$5*100 -> 10.762535 | J12: =F12-H12 -> -304938000 | K12: =J12/H12*100 -> -53.503714
E13: 623-02 간접관리비수익 | F13: =수입예산!G79 -> 35000000 | G13: =F13/$F$5*100 -> 0.65543071 | H13: =수입예산!H79 -> 165636000 | I13: =H13/$H$5*100 -> 3.1278196 | J13: =F13-H13 -> -130636000 | K13: =J13/H13*100 -> -78.869328
D14: 646 보조금수익 | F14: =SUM(F15:F17) -> 0 | G14: =F14/$F$5*100 -> 0 | H14: =SUM(H15:H17) -> 0 | I14: =H14/$H$5*100 -> 0 | J14: =F14-H14 -> 0 | K14: =J14/H14*100 -> #DIV/0!
E15: 646-01 국비보조금수익 | F15: 0 | G15: =F15/$F$5*100 -> 0 | H15: 0 | I15: =H15/$H$5*100 -> 0 | J15: =F15-H15 -> 0 | K15: =J15/H15*100 -> #DIV/0!
E16: 646-02 자치단체보조금수익 | F16: =수입예산!G86 -> 0 | G16: =F16/$F$5*100 -> 0 | H16: =수입예산!H86 -> 0 | I16: =H16/$H$5*100 -> 0 | J16: =F16-H16 -> 0 | K16: =J16/H16*100 -> #DIV/0!
E17: 646-03 기타보조금수익 | F17: =수입예산!G88 -> 0 | G17: =F17/$F$5*100 -> 0 | H17: =수입예산!H88 -> 0 | I17: =H17/$H$5*100 -> 0 | J17: =F17-H17 -> 0
D18: 648 출연금수익 | F18: =SUM(F19:F22) -> 100000000 | G18: =F18/$F$5*100 -> 1.8726592 | H18: =SUM(H19:H22) -> 100000000 | I18: =H18/$H$5*100 -> 1.8883694 | J18: =F18-H18 -> 0 | K18: =J18/H18*100 -> 0
E19: 625-01 국고출연금 | F19: 0 | G19: =F19/$F$5*100 -> 0 | H19: 0 | I19: =H19/$H$5*100 -> 0 | J19: =F19-H19 -> 0 | K19: =J19/H19*100 -> #DIV/0!
E20: 648-01 정부출연금수익 | F20: 0 | G20: =F20/$F$5*100 -> 0 | H20: 0 | I20: =H20/$H$5*100 -> 0 | J20: =F20-H20 -> 0 | K20: =J20/H20*100 -> #DIV/0!
E21: 648-02 자치단체출연금수익 | F21: =수입예산!G91 -> 100000000 | G21: =F21/$F$5*100 -> 1.8726592 | H21: =수입예산!H91 -> 100000000 | I21: =H21/$H$5*100 -> 1.8883694 | J21: =F21-H21 -> 0 | K21: =J21/H21*100 -> 0
E22: 648-03-기타출연금수익 | F22: 0 | G22: =F22/$F$5*100 -> 0 | H22: 0 | I22: =H22/$H$5*100 -> 0 | J22: =F22-H22 -> 0 | K22: =J22/H22*100 -> #DIV/0!
D23: 650 출연금이자수익 | F23: =F24 -> 0 | G23: =F23/$F$5*100 -> 0 | H23: =H24 -> 0 | I23: 0 | J23: =F23-H23 -> 0 | K23: =J23/H23*100 -> #DIV/0!
E24: 650-01 출연금 이자수익 | F24: 0 | G24: =F24/$F$5*100 -> 0 | H24: 0 | I24: 0 | J24: =F24-H24 -> 0 | K24: =J24/H24*100 -> #DIV/0!
D25: 651 연구용역수익 | F25: =SUM(F26) -> 0 | G25: =F25/$F$5*100 -> 0 | H25: =H26 -> 0 | I25: 0 | J25: =F25-H25 -> 0 | K25: =J25/H25*100 -> #DIV/0!
E26: 651-01 연구용역수익 | F26: =수입예산!G95 -> 0 | G26: =F26/$F$5*100 -> 0 | H26: =수입예산!H95 -> 0 | I26: 0 | J26: =F26-H26 -> 0 | K26: =J26/H26*100 -> #DIV/0!
C27: 670 영업외수익 | F27: =F28+F30 -> 0 | G27: =F27/$F$5*100 -> 0 | H27: =H28+H30 -> 0 | I27: =H27/$H$5*100 -> 0 | J27: =F27-H27 -> 0 | K27: =J27/H27*100 -> #DIV/0!
D28: 671 이자수익 | F28: =F29 -> 0 | G28: =F28/$F$5*100 -> 0 | H28: =H29 -> 0 | I28: =H28/$H$5*100 -> 0 | J28: =F28-H28 -> 0 | K28: =J28/H28*100 -> #DIV/0!
E29: 671-01 예금이자수익 | F29: =수입예산!G99 -> 0 | G29: =F29/$F$5*100 -> 0 | H29: =수입예산!H99 -> 0 | I29: =H29/$H$5*100 -> 0 | J29: =F29-H29 -> 0 | K29: =J29/H29*100 -> #DIV/0!
D30: 679 기타영업외수익 | F30: =F31 -> 0 | G30: =F30/$F$5*100 -> 0 | H30: =H31 -> 0 | I30: =H30/$H$5*100 -> 0 | J30: =F30-H30 -> 0 | K30: =J30/H30*100 -> #DIV/0!
E31: 679-09 기타영업외수익 | F31: =수입예산!G102 -> 0 | G31: =F31/$F$5*100 -> 0 | H31: =수입예산!H102 -> 0 | I31: =H31/$H$5*100 -> 0 | J31: =F31-H31 -> 0 | K31: =J31/H31*100 -> #DIV/0!
B32: 100 자본적 수입 | F32: =F33+F44+F50 -> 4000000000 | G32: =F32/$F$5*100 -> 74.906367 | H32: =H33+H44+H50 -> 3410000000 | I32: =H32/$H$5*100 -> 64.393397 | J32: =F32-H32 -> 590000000 | K32: =J32/H32*100 -> 17.302053
C33: 120 유형자산처분 | F33: =F34+F39 -> 0 | G33: =F33/$F$5*100 -> 0 | H33: =H34+H39 -> 0 | I33: =H33/$H$5*100 -> 0 | J33: =F33-H33 -> 0 | K33: =J33/H33*100 -> #DIV/0!
D34: 121 재산매각수입 | F34: =SUM(F35:F38) -> 0 | G34: =F34/$F$5*100 -> 0 | H34: =SUM(H35:H38) -> 0 | I34: =H34/$H$5*100 -> 0 | J34: =F34-H34 -> 0 | K34: =J34/H34*100 -> #DIV/0!
E35: 121-01 토지 | F35: 0 | G35: =F35/$F$5*100 -> 0 | H35: 0 | I35: =H35/$H$5*100 -> 0 | J35: =F35-H35 -> 0 | K35: =J35/H35*100 -> #DIV/0!
E36: 121-02 건물 | F36: 0 | G36: =F36/$F$5*100 -> 0 | H36: 0 | I36: =H36/$H$5*100 -> 0 | J36: =F36-H36 -> 0 | K36: =J36/H36*100 -> #DIV/0!
E37: 121-03 구축물 | F37: 0 | G37: =F37/$F$5*100 -> 0 | H37: 0 | I37: =H37/$H$5*100 -> 0 | J37: =F37-H37 -> 0 | K37: =J37/H37*100 -> #DIV/0!
E38: 121-04 입목 | F38: 0 | G38: =F38/$F$5*100 -> 0 | H38: 0 | I38: =H38/$H$5*100 -> 0 | J38: =F38-H38 -> 0 | K38: =J38/H38*100 -> #DIV/0!
D39: 122 물품매각수입 | F39: =SUM(F40:F43) -> 0 | G39: =F39/$F$5*100 -> 0 | H39: =SUM(H40:H43) -> 0 | I39: =H39/$H$5*100 -> 0 | J39: =F39-H39 -> 0 | K39: =J39/H39*100 -> #DIV/0!
E40: 122-01 기계장치매각수입 | F40: 0 | G40: =F40/$F$5*100 -> 0 | H40: 0 | I40: =H40/$H$5*100 -> 0 | J40: =F40-H40 -> 0 | K40: =J40/H40*100 -> #DIV/0!
E41: 122-02 차량운반구매각수입 | F41: 0 | G41: =F41/$F$5*100 -> 0 | H41: 0 | I41: =H41/$H$5*100 -> 0 | J41: =F41-H41 -> 0 | K41: =J41/H41*100 -> #DIV/0!
...

Sheet 3-5.지출예산 성질별총괄표(완료)
B1: 3-5. 지출예산 성질별 총괄표
K2: (단위 : 천원)
B3: 구 분 | F3: 본예산액 | G3: 구성비 | H3: 전년도 본예산액 | I3: 구성비 | J3: 증감 | K3: 증감률
B5: 합 계 | F5: =F6+F59+F75 -> 32072175407 | G5: =F5/$F$5*100 -> 100 | H5: =H6+H59+H75 -> 41866399552 | I5: =H5/$H$5*100 -> 100 | J5: =F5-H5 -> -9794224145 | K5: =J5/H5*100 -> -23.393997
B6: 700 사업비용 | F6: =F7+F52 -> 26426013407 | G6: =F6/$F$5*100 -> 82.39545 | H6: =H7+H52 -> 29860697552 | I6: =H6/$H$5*100 -> 71.323777 | J6: =F6-H6 -> -3434684145 | K6: =J6/H6*100 -> -11.502357
C7: 710 영업비용 | F7: =F8+F11+F12+F19+F22+F24+F27+F29+F33+F34+F36+F37+F40+F41+F42+F45+F47+F49+F51 -> 26426013407 | G7: =F7/$F$5*100 -> 82.39545 | H7: =H8+H11+H12+H19+H22+H24+H27+H29+H33+H34+H36+H37+H40+H41+H42+H45+H47+H49+H51 -> 29853197552 | I7: =H7/$H$5*100 -> 71.305863 | J7: =F7-H7 -> -3427184145 | K7: =J7/H7*100 -> -11.480124
D8: 101 인건비 | F8: =SUM(F9:F10) -> 10495421913 | G8: =F8/$F$5*100 -> 32.724384 | H8: =SUM(H9:H10) -> 12222887892 | I8: =H8/$H$5*100 -> 29.194982 | J8: =F8-H8 -> -1727465979 | K8: =J8/H8*100 -> -14.133043
E9: 01 보수 | F9: 9998339599 | G9: =F9/$F$5*100 -> 31.174498 | H9: 11015063892 | I9: =H9/$H$5*100 -> 26.310034 | J9: =F9-H9 -> -1016724293 | K9: =J9/H9*100 -> -9.2303077
E10: 04 기간제근로자보수 | F10: 497082314 | G10: =F10/$F$5*100 -> 1.5498865 | H10: 1207824000 | I10: =H10/$H$5*100 -> 2.8849483 | J10: =F10-H10 -> -710741686 | K10: =J10/H10*100 -> -58.844806
D11: 107 퇴직급여 | F11: 1036569000 | G11: =F11/$F$5*100 -> 3.2319884 | H11: 853779000 | I11: =H11/$H$5*100 -> 2.0392941 | J11: =F11-H11 -> 182790000 | K11: =J11/H11*100 -> 21.409522
D12: 201 일반운영비 | F12: =SUM(F13:F18) -> 2809940000 | G12: =F12/$F$5*100 -> 8.7613015 | H12: =SUM(H13:H18) -> 3088183000 | I12: =H12/$H$5*100 -> 7.3762803 | J12: =F12-H12 -> -278243000 | K12: =J12/H12*100 -> -9.0099259
E13: 01 사무관리비 | F13: 1197132000 | G13: =F13/$F$5*100 -> 3.7326186 | H13: 1111757000 | I13: =H13/$H$5*100 -> 2.6554875 | J13: =F13-H13 -> 85375000 | K13: =J13/H13*100 -> 7.679286
E14: 02 공공운영비 | F14: 502051000 | G14: =F14/$F$5*100 -> 1.5653787 | H14: 703292000 | I14: =H14/$H$5*100 -> 1.6798483 | J14: =F14-H14 -> -201241000 | K14: =J14/H14*100 -> -28.614146
E15: 03 행사운영비 | F15: 619032000 | G15: =F15/$F$5*100 -> 1.9301216 | H15: 691260000 | I15: =H15/$H$5*100 -> 1.6511093 | J15: =F15-H15 -> -72228000 | K15: =J15/H15*100 -> -10.448746
E16: 14 회의비 | F16: 145032000 | G16: =F16/$F$5*100 -> 0.45220506 | H16: 120644000 | I16: =H16/$H$5*100 -> 0.28816426 | J16: =F16-H16 -> 24388000 | K16: =J16/H16*100 -> 20.214847
E17: 15 복리후생비 | F17: 316893000 | G17: =F17/$F$5*100 -> 0.98806207 | H17: 387054000 | I17: =H17/$H$5*100 -> 0.92449794 | J17: =F17-H17 -> -70161000 | K17: =J17/H17*100 -> -18.126928
E18: 16 광고선전비 | F18: 29800000 | G18: =F18/$F$5*100 -> 0.092915431 | H18: 74176000 | I18: =H18/$H$5*100 -> 0.1771731 | J18: =F18-H18 -> -44376000 | K18: =J18/H18*100 -> -59.82528
D19: 202 여비 | F19: =SUM(F20:F21) -> 520360000 | G19: =F19/$F$5*100 -> 1.6224656 | H19: =SUM(H20:H21) -> 440364000 | I19: =H19/$H$5*100 -> 1.0518316 | J19: =F19-H19 -> 79996000 | K19: =J19/H19*100 -> 18.165881
E20: 01 국내여비 | F20: 387502000 | G20: =F20/$F$5*100 -> 1.2082186 | H20: 351734000 | I20: =H20/$H$5*100 -> 0.84013434 | J20: =F20-H20 -> 35768000 | K20: =J20/H20*100 -> 10.169048
E21: 03 국외업무여비 | F21: 132858000 | G21: =F21/$F$5*100 -> 0.41424692 | H21: 88630000 | I21: =H21/$H$5*100 -> 0.21169721 | J21: =F21-H21 -> 44228000 | K21: =J21/H21*100 -> 49.901839
D22: 203 업무추진비 | F22: =SUM(F23) -> 71100000 | G22: =F22/$F$5*100 -> 0.22168749 | H22: =SUM(H23) -> 72600000 | I22: =H22/$H$5*100 -> 0.17340875 | J22: =F22-H22 -> -1500000 | K22: =J22/H22*100 -> -2.0661157
E23: 07 사업업무추진비 | F23: 71100000 | G23: =F23/$F$5*100 -> 0.22168749 | H23: 72600000 | I23: =H23/$H$5*100 -> 0.17340875 | J23: =F23-H23 -> -1500000 | K23: =J23/H23*100 -> -2.0661157
D24: 204 직무수행경비 | F24: =SUM(F25:F26) -> 78480000 | G24: =F24/$F$5*100 -> 0.24469809 | H24: =SUM(H25:H26) -> 86160000 | I24: =H24/$H$5*100 -> 0.20579749 | J24: =F24-H24 -> -7680000 | K24: =J24/H24*100 -> -8.913649
E25: 01 직급보조비 | F25: 56400000 | G25: =F25/$F$5*100 -> 0.17585337 | H25: 56400000 | I25: =H25/$H$5*100 -> 0.13471424 | J25: =F25-H25 -> 0 | K25: =J25/H25*100 -> 0
E26: 02 특정업무경비 | F26: 22080000 | G26: =F26/$F$5*100 -> 0.068844722 | H26: 29760000 | I26: =H26/$H$5*100 -> 0.071083256 | J26: =F26-H26 -> -7680000 | K26: =J26/H26*100 -> -25.806452
D27: 206 재료비 | F27: =F28 -> 435450000 | G27: =F27/$F$5*100 -> 1.3577189 | H27: =H28 -> 639650000 | I27: =H27/$H$5*100 -> 1.5278362 | J27: =F27-H27 -> -204200000 | K27: =J27/H27*100 -> -31.923708
E28: 01 일반재료비 | F28: 435450000 | G28: =F28/$F$5*100 -> 1.3577189 | H28: 639650000 | I28: =H28/$H$5*100 -> 1.5278362 | J28: =F28-H28 -> -204200000 | K28: =J28/H28*100 -> -31.923708
D29: 207 연구개발비 | F29: =SUM(F30:F32) -> 964619000 | G29: =F29/$F$5*100 -> 3.0076507 | H29: =SUM(H30:H32) -> 1398835000 | I29: =H29/$H$5*100 -> 3.3411877 | J29: =F29-H29 -> -434216000 | K29: =J29/H29*100 -> -31.041259
E30: 01 연구용역비 | F30: 185600000 | G30: =F30/$F$5*100 -> 0.57869476 | H30: 161500000 | I30: =H30/$H$5*100 -> 0.38575087 | J30: =F30-H30 -> 24100000 | K30: =J30/H30*100 -> 14.922601
E31: 02 전산개발비 | F31: 0 | G31: =F31/$F$5*100 -> 0 | H31: 400000000 | I31: =H31/$H$5*100 -> 0.95542011 | J31: =F31-H31 -> -400000000 | K31: =J31/H31*100 -> -100
E32: 03 시험연구비 | F32: 779019000 | G32: =F32/$F$5*100 -> 2.4289559 | H32: 837335000 | I32: =H32/$H$5*100 -> 2.0000167 | J32: =F32-H32 -> -58316000 | K32: =J32/H32*100 -> -6.9644766
D33: 213 교육훈련비 | F33: 176250000 | G33: =F33/$F$5*100 -> 0.54954177 | H33: 342416000 | I33: =H33/$H$5*100 -> 0.81787783 | J33: =F33-H33 -> -166166000 | K33: =J33/H33*100 -> -48.527522
D34: 214 수선유지교체비 | F34: =F35 -> 1307423494 | G34: =F34/$F$5*100 -> 4.0765039 | H34: =H35 -> 1127200000 | I34: =H34/$H$5*100 -> 2.6923739 | J34: =F34-H34 -> 180223494 | K34: =J34/H34*100 -> 15.9886
E35: 05 수선유지비 | F35: 1307423494 | G35: =F35/$F$5*100 -> 4.0765039 | H35: 1127200000 | I35: =H35/$H$5*100 -> 2.6923739 | J35: =F35-H35 -> 180223494 | K35: =J35/H35*100 -> 15.9886
D36: 215 동력비 | F36: 3127162000 | G36: =F36/$F$5*100 -> 9.7503894 | H36: 3091800000 | I36: =H36/$H$5*100 -> 7.3849197 | J36: =F36-H36 -> 35362000 | K36: =J36/H36*100 -> 1.143735
D37: 217 관서업무비 | F37: =SUM(F38:F39) -> 43140000 | G37: =F37/$F$5*100 -> 0.13450912 | H37: =SUM(H38:H39) -> 44630000 | I37: =H37/$H$5*100 -> 0.106601 | J37: =F37-H37 -> -1490000 | K37: =J37/H37*100 -> -3.3385615
E38: 01 정원가산업무비 | F38: 12240000 | G38: =F38/$F$5*100 -> 0.038163922 | H38: 12620000 | I38: =H38/$H$5*100 -> 0.030143504 | J38: =F38-H38 -> -380000 | K38: =J38/H38*100 -> -3.0110935
E39: 02 부서업무비 | F39: 30900000 | G39: =F39/$F$5*100 -> 0.096345195 | H39: 32010000 | I39: =H39/$H$5*100 -> 0.076457494 | J39: =F39-H39 -> -1110000 | K39: =J39/H39*100 -> -3.4676664
D40: 218 평가급 | F40: 1097405000 | G40: =F40/$F$5*100 -> 3.4216731 | H40: 1176999500 | I40: =H40/$H$5*100 -> 2.8113225 | J40: =F40-H40 -> -79594500 | K40: =J40/H40*100 -> -6.7624923
D41: 220 위탁관리비 | F41: 677656000 | G41: =F41/$F$5*100 -> 2.1129094 | H41: 1058334000 | I41: =H41/$H$5*100 -> 2.527884 | J41: =F41-H41 -> -380678000 | K41: =J41/H41*100 -> -35.969552
...

Sheet 수입예산 표지
B16: 4. 수입예산

Sheet 수입예산
B1: 수 입 예 산
I2: (단위 : 천원) | S2: (단위 : 원, 명, 일, 회, 식)
B3: 과 목 | G3: 예산액 | H3: 전년도 본예산액 | I3: 증 감 | J3: 산 출 기 초
B4: 부 서 | C4: 관 | D4: 항 | E4: 세항 | F4: 목 | G4: (A) | H4: (B) | I4: (A-B)
B5: 수 입 총 계 | G5: =G6 -> 5340000000 | H5: =H6 -> 5295574000 | I5: =I6 -> 44426000
B6: 진흥원 수입 총계 | G6: =G7+G104 -> 5340000000 | H6: =H7+H104 -> 5295574000 | I6: =I7+I104 -> 44426000
C7: 600 사업수익 | G7: =G8+G97 -> 1340000000 | H7: =H8+H97 -> 1885574000 | I7: =I8+I97 -> -545574000
D8: 610 영업수익 | G8: =G9+G21+G85+G90+G94 -> 1340000000 | H8: =H9+H21+H85+H90+H94 -> 1885574000 | I8: =I9+I21+I85+I90+I94 -> -545574000
E9: 622 관리사업수익 | G9: =G10 -> 940000000 | H9: =H10 -> 1050000000 | I9: =I10 -> -110000000
F10: 622-01 | G10: =S10 -> 940000000 | H10: 1050000000 | I10: =G10-H10 -> -110000000 | J10: ▶ | K10: 관리사업수익 | S10: =SUM(S11:S20) -> 940000000
J11: □ | K11: 기타장비활용수익 | S11: =SUM(R12:R13) -> 350000000
K12: 나노센터
K13: ◦ 고차가공장비 활용수익 | Q13: = | R13: 350000000
J14: □ | K14: 임대료수익 | S14: =SUM(R15:R18) -> 540000000
K15: 나노센터
K16: ◦ 임대료수익 | Q16: = | R16: 240000000
K17: ◦ 임대관리수익 | Q17: = | R17: 150000000
K18: ◦ 클린룸 임대료수익 | Q18: = | R18: 150000000
J19: □ | K19: 기술료 수익 | S19: =SUM(R20:R20) -> 50000000
K20: ◦ 나노센터 기술이전 기술료 | Q20: = | R20: 50000000
E21: 623 대행사업수익 | G21: =G22+G79 -> 300000000 | H21: =H22+H79 -> 735574000 | I21: =I22+I79 -> -435574000
F22: 623-01 | G22: =S22 -> 265000000 | H22: 569938000 | I22: =G22-H22 -> -304938000 | J22: ▶ | K22: 직접관리비수익 | S22: =SUM(S23:S27) -> 265000000
F23: 직접관리비수익 | J23: □ | K23: 국비 | S23: =SUM(R24:R27) -> 265000000
K24: 나노센터
K25: ◦ 25년 창업성장기술개발사업(디이노잔틴) | P25: (중기부) | Q25: = | R25: 45000000
K26: ◦ 24년 국제공동기술개발사업(귀뚜라미) 2차년도(산업부)(AI융합지원실) | Q26: = | R26: 45000000
K27: ◦ 25년 광주연구개발특구(유니콘)(AI융합지원실) | P27: (과기부) | Q27: = | R27: 175000000
K28: ◦ 24년 연구기반활용사업(중기부) | Q28: =
K29: 천연자원연구센터
K30: ◦ 진균류 바이오 헬스 소재 상용화 지원 사업 (3차) | P30: (산자부) | Q30: =
K31: ◦ 바이오활성제제 글로벌 경쟁력 강화 (4차) | P31: (산자부) | Q31: =
K32: ◦ 면역강화를 위한 원예 특용자원의 효능 향상과 생산 표준화 기술 개발 (3차) | P32: (농진청) | Q32: =
K33: ◦ 무화과 부가가치 증진을 위한 상품 개발 및 저장 유통 개선 연구 사업 (2차) | P33: (농진청) | Q33: =
K34: ◦ 자생 붉가시나무 부산물의 주름개선 복합기능성 화장품 소재 개발 사업 (2차) | P34: (산림청) | Q34: =
K35: 해양바이오연구센터
K36: ◦ 전남해양수산창업투자지원센터 | P36: (해수부) | Q36: =
K37: ◦ 해양치유자원의 관리 및 활용기술 개발 | P37: (해수부, 산림청) | Q37: =
K38: ◦ 중소기업기술혁신개발사업 수출지향형(피부재생패치) | P38: (중기부) | Q38: =
K39: ◦ 시군구연고산업육성사업 | P39: (중기부) | Q39: =
K40: 친환경농생명연구센터
...

Sheet 지출예산
J2: (단위 : 천원) | W2: (단위 : 원, 명, 일, 월, 시간, 회, 개, 식, 박스, ㎡)
H3: 예 산 액 | I3: 전년도 본예산액 | J3: 증 감 | K3: 산 출 기 초
B4: 사 업 | C4: 관 | D4: 항 | E4: 세 항 | F4: 목 | G4: 세목 | H4: (A) | I4: (B) | J4: (A - B)
B5: 지 출 총 계 | H5: =SUM(H6:H11) -> 4797520000 | I5: =SUM(I6:I11) -> 5492303000 | J5: =SUM(J6:J11) -> -694783000
B6: 진흥원 대행사업비용( A ) | H6: =H12 -> 4265000000 | I6: =I12 -> 5033143000 | J6: =J12 -> -768143000
B7: 진흥원 목적사업비용(B) | H7: =H111 -> 0 | I7: =I111 -> 0 | J7: =J111 -> 0
B8: 진흥원 일반관리비용(C) | H8: =H112 -> 463280000 | I8: =I112 -> 381160000 | J8: =J112 -> 82120000
B9: 진흥원 장비사업원가(D) | H9: =H254 -> 47900000 | I9: =I254 -> 62000000 | J9: =J254 -> -14100000
B10: 진흥원 분석사업원가(E) | H10: =H299 -> 0 | I10: =I299 -> 0 | J10: =J299 -> 0
B11: 진흥원 임대사업원가(F) | H11: =H300 -> 21340000 | I11: =I300 -> 16000000 | J11: =J300 -> 5340000
B12: 대행사업비용( A ) | H12: =H13+H24+H51+H84+H108+H109+H110 -> 4265000000 | I12: =I13+I24+I51+I84+I108+I109+I110 -> 5033143000 | J12: =H12-I12 -> -768143000
B13: 초임계 원료의약품생산플랫폼구축사업(4차년도) | H13: =H14 -> 4000000000 | I13: =I14 -> 3000000000 | J13: =H13-I13 -> 1000000000
C14: 200 자본적지출 | H14: =H15 -> 4000000000 | I14: =I15 -> 3000000000 | J14: =J15 -> -2000000000
D15: 230 유형자산취득 | H15: =H16+H20 -> 4000000000 | I15: =I16 -> 3000000000 | J15: =J16 -> -2000000000
E16: 233 건물 | H16: =H17 -> 1000000000 | I16: =I17 -> 3000000000 | J16: =J17 -> -2000000000
F17: 401 시설비및부대비 | H17: =H18 -> 1000000000 | I17: =I18 -> 3000000000 | J17: =J18 -> -2000000000
G18: 01 시설비 | H18: 1000000000 | I18: 3000000000 | J18: =H18-I18 -> -2000000000 | K18: ▶ | L18: 시설비 | W18: =V19 -> 1000000000
L19: ◦ 건축공사비 | P19: 1000000000 | S19: X | T19: 1 | U19: = | V19: =P19*T19 -> 1000000000
E20: 235 기계장치 | H20: =H21 -> 3000000000 | I20: =I21 -> 0 | J20: =J21 -> 3000000000
F21: 405 자산취득비 | H21: =H22 -> 3000000000 | I21: =I22 -> 0 | J21: =J22 -> 3000000000
G22: 01 자산취득비 | H22: =W22 -> 3000000000 | I22: 0 | J22: =H22-I22 -> 3000000000 | K22: ▶ | L22: 기계장치 | W22: =V23 -> 3000000000
L23: ◦ 초임계 유체 크로마토그래피 외 | P23: 3000000000 | S23: X | T23: 1 | U23: = | V23: =P23*T23 -> 3000000000
B24: 2025 디딤돌과제(디아노잔틴) | H24: =H25 -> 45000000 | I24: =I25 -> 0 | J24: =J25 -> 45000000
C25: 700 사업비용 | H25: =H26 -> 45000000 | I25: =I26 -> 0 | J25: =J26 -> 45000000
D26: 710 영업비용 | H26: =H27 -> 45000000 | I26: =I27 -> 0 | J26: =J27 -> 45000000
E27: 722 대행사업비 | H27: =H28+H33+H38+H41+H48 -> 45000000 | I27: =I28+I33+I38+I41+I48 -> 0 | J27: =H27-I27 -> 45000000
F28: 101 인건비 | H28: =H29 -> 24000000 | I28: =I29 -> 0 | J28: =H28-I28 -> 24000000
G29: 01 보수 | H29: =I29+W29 -> 24000000 | I29: 0 | J29: =H29-I29 -> 24000000 | K29: ▶ | L29: 참여연구원 보수 | W29: =SUM(V30:V32) -> 24000000
L30: ◦ 책임급 | N30: 5000000 | O30: X | P30: 1 | Q30: X | R30: 12 | S30: X | T30: 0.1 | U30: = | V30: =N30*P30*R30*T30 -> 6000000
L31: ◦ 선임급 | N31: 4000000 | O31: X | P31: 2 | Q31: X | R31: 12 | S31: X | T31: 0.1 | U31: = | V31: =N31*P31*R31*T31 -> 9600000
L32: ◦ 주임급 | N32: 3500000 | O32: X | P32: 2 | Q32: X | R32: 12 | S32: X | T32: 0.1 | U32: = | V32: =N32*P32*R32*T32 -> 8400000
F33: 201 일반운영비 | H33: =H34+H36 -> 2200000 | I33: =I36 -> 0 | J33: =H33-I33 -> 2200000
G34: 01 사무관리비 | H34: =I34+W34 -> 500000 | I34: 0 | J34: =H34-I34 -> 500000 | K34: ▶ | L34: 사무관리비 | W34: =V35 -> 500000
L35: ◦ 사무용품비 | P35: 500000 | Q35: X | R35: 1 | S35: X | T35: 1 | U35: = | V35: =P35*R35*T35 -> 500000
G36: 14 회의비 | H36: =I36+W36 -> 1700000 | I36: 0 | J36: =H36-I36 -> 1700000 | K36: ▶ | L36: 회의비 | W36: =V37 -> 1700000
L37: ◦ 사업관련 회의비 | P37: 170000 | Q37: X | R37: 1 | S37: X | T37: 10 | U37: = | V37: =P37*R37*T37 -> 1700000
F38: 202 여비 | H38: =H39 -> 3000000 | I38: =I39 -> 0 | J38: =J39 -> 3000000
G39: 01 국내여비 | H39: =I39+W39 -> 3000000 | I39: 0 | J39: =H39-I39 -> 3000000 | K39: ▶ | L39: 국내여비 | W39: =V40 -> 3000000
L40: ◦ 업무출장여비 | P40: 100000 | Q40: X | R40: 5 | S40: X | T40: 6 | U40: = | V40: =P40*R40*T40 -> 3000000
F41: 207 연구개발비 | H41: =H42 -> 11000000 | I41: =I42 -> 0 | J41: =J42 -> 11000000
...

Sheet 지출예산 표지
B16: 5. 지출예산

Sheet 자금운영계획(표지)
B16: 6. 자금운영계획

Sheet 6.자금운영계획(완료)
B1: 6. 자금운영계획
B2: (1) 수입자금
F3: (단위 : 천원) | L3: (단위 : 천원)
B4: 구 분 | D4: 예산액 | E4: 전년도본예산액 | F4: 증 감 | H4: 구 분 | J4: 예산액 | K4: 전년도본예산액 | L4: 증 감
D6: (A') | E6: (B') | F6: (A'-B') | J6: (A') | K6: (B') | L6: (A'-B')
B7: 수 입 자 금 (A) | D7: =SUM(D8,D17,J16,J22,J25) -> 28927786061 | E7: =SUM(E8,E17,K16,K22,K25) -> 21798618283 | F7: =SUM(F8,F17,L16,L25) -> 7129167778 | H7: 고정부채수입 | I7: 계
B8: 영업수익 | C8: 계 | D8: =SUM(D9:D13) -> 1340000000 | E8: =SUM(E9:E13) -> 1885574000 | F8: =SUM(F9:F13) -> -545574000 | I8: 외국차관
C9: 관리사업수익 | D9: ='3-4. 수입예산 성질별 총괄표(완료)'!F8 -> 940000000 | E9: ='3-4. 수입예산 성질별 총괄표(완료)'!H8 -> 1050000000 | F9: =D9-E9 -> -110000000
C10: 대행사업수익 | D10: ='3-4. 수입예산 성질별 총괄표(완료)'!F11 -> 300000000 | E10: ='3-4. 수입예산 성질별 총괄표(완료)'!H11 -> 735574000 | F10: =D10-E10 -> -435574000 | I10: 사채
C11: 보조금수익 | D11: ='3-4. 수입예산 성질별 총괄표(완료)'!F14 -> 0 | E11: ='3-4. 수입예산 성질별 총괄표(완료)'!H14 -> 0 | F11: =D11-E11 -> 0
C12: 출연금수익 | D12: ='3-4. 수입예산 성질별 총괄표(완료)'!F18 -> 100000000 | E12: ='3-4. 수입예산 성질별 총괄표(완료)'!H18 -> 100000000 | F12: =D12-E12 -> 0
C13: 연구용역수익 | D13: ='3-4. 수입예산 성질별 총괄표(완료)'!F25 -> 0 | E13: ='3-4. 수입예산 성질별 총괄표(완료)'!H25 -> 0 | F13: =D13-E13 -> 0
O14: .
H16: 자본잉여금수입 | I16: 계 | J16: =SUM(J17:J18) -> 4000000000 | K16: =SUM(K17:K18) -> 3410000000 | L16: =J16-K16 -> 590000000
B17: 영업외수익 | C17: 계 | D17: =SUM(D18:D20) -> 0 | E17: =SUM(E18:E20) -> 0 | F17: =SUM(F18:F20) -> 0 | I17: 보조금 | J17: ='3-4. 수입예산 성질별 총괄표(완료)'!F45 -> 0 | K17: ='3-4. 수입예산 성질별 총괄표(완료)'!H45 -> 0 | L17: =J17-K17 -> 0
C18: 이자수익 | D18: ='3-4. 수입예산 성질별 총괄표(완료)'!F28 -> 0 | E18: ='3-4. 수입예산 성질별 총괄표(완료)'!H28 -> 0 | F18: =D18-E18 -> 0 | I18: 수탁자산보조금 | J18: ='3-4. 수입예산 성질별 총괄표(완료)'!F48 -> 4000000000 | K18: ='3-4. 수입예산 성질별 총괄표(완료)'!H48 -> 3410000000 | L18: =J18-K18 -> 590000000
C19: 유형자산처분수익 | F19: =D19-E19 -> 0
C20: 기타영업외수익 | D20: ='3-4. 수입예산 성질별 총괄표(완료)'!F30 -> 0 | E20: ='3-4. 수입예산 성질별 총괄표(완료)'!H30 -> 0 | F20: =D20-E20 -> 0 | H20: 자본금 | I20: 계
I21: 자본금
B22: 특 별 이 익 | C22: 계 | H22: 기타자본적수입 | I22: 계
C23: 기타특별이익 | I23: 기타자본적수입
B24: 투자자산 수입 | C24: 계
C25: 대여금 | H25: 전년도이월금 | I25: 계 | J25: =SUM(J26:J28) -> 23587786061 | K25: =SUM(K26:K28) -> 16503044283 | L25: =SUM(L26:L28) -> 7084741778
C26: 기타투자자산 | I26: 보통재산(운영재산) | J26: ='3-4. 수입예산 성질별 총괄표(완료)'!F50 -> 0 | K26: ='3-4. 수입예산 성질별 총괄표(완료)'!H50 -> 0 | L26: =J26-K26 -> 0
B27: 고정자산 매각수입 | C27: 계 | I27: 이월금(계속비포함) | J27: =21526805340+7224721 -> 21534030061 | K27: =16465337963+37706320 -> 16503044283 | L27: =J27-K27 -> 5030985778
C28: 토지 | I28: 미지급이월금 | J28: 2053756000 | K28: 0 | L28: =J28-K28 -> 2053756000
C29: 건물
C30: 구축물
C31: 기계장치
C32: 차량운반구
C33: 공기구비품
C34: 기타유형자산
B35: 6. 자금운영계획
B36: (2) 지출자금
F38: (단위 : 천원) | L38: (단위 : 천원)
B39: 구 분 | D39: 예산액 | E39: 전년도본예산액 | F39: 증 감 | H39: 구 분 | J39: 예산액 | K39: 전년도본예산액 | L39: 증 감
D41: (A') | E41: (B') | F41: (A'-B') | J41: (A') | K41: (B') | L41: (A'-B')
B42: 지 출 자 금 (B) | D42: =SUM(D43,D50,D52,D55,D56,D57,D61,J42,J45,J47,J53,J55)+J59 -> 55659961468 | E42: =SUM(E43,E50,E52,E55,E56,E57,E61,K42,K45,K47,K53,K55)+K59 -> 58369443835 | F42: =D42-E42-1000 -> -2709483367 | H42: 무형자산 | I42: 계 | J42: =SUM(J43:J44) -> 155500000 | K42: =SUM(K43:K44) -> 99000000 | L42: =SUM(L43:L44) -> 56500000
B43: 영업비용 | C43: 계 | D43: =SUM(D44:D49) -> 26426013407 | E43: =SUM(E44:E49) -> 29853197552 | F43: =SUM(F44:F49) -> -3427184145 | I43: 특허권 | J43: ='3-3.자본예산총괄표(완료)'!G15 -> 95500000 | K43: ='3-5.지출예산 성질별총괄표(완료)'!H70 -> 99000000 | L43: =J43-K43 -> -3500000
C44: 인건비, 퇴직급여 등 | D44: ='3-2.사업예산총괄표(완료)'!G6 -> 12421870913 | E44: ='3-5.지출예산 성질별총괄표(완료)'!H8+'3-5.지출예산 성질별총괄표(완료)'!H11+'3-5.지출예산 성질별총괄표(완료)'!H26+'3-5.지출예산 성질별총괄표(완료)'!H47 -> 14147890052 | F44: =D44-E44 -> -1726019139 | I44: 정보화시스템 | J44: ='3-3.자본예산총괄표(완료)'!G16 -> 60000000 | K44: ='3-5.지출예산 성질별총괄표(완료)'!H72 -> 0 | L44: =J44-K44 -> 60000000 | N44: ='3-5.지출예산 성질별총괄표(완료)'!H7 -> 29853197552
...

Sheet 7.별첨자료(표지)
B16: 7. 별 첨 자 료

Sheet 별첨7-1. 임직원 인건비(완료)
B1: <별첨 7-1> 임직원 등의 인건비 | G1: (단위 : 천원)
B2: 구분 | C2: 인원수(명) | D2: 인 건 비 | G2: 1인당 평균임금
D3: 전년도 | E3: 당해년도 | F3: 증감
B5: 계 | C5: =SUM(C6:C7) -> 162 | D5: ='3-5.지출예산 성질별총괄표(완료)'!H9 -> 11015063892 | E5: 10243150052 | F5: =SUM(F6:F7) -> -771913840 | G5: =E5/C5 -> 63229321
B6: 임원 (비상임 제외) | C6: 1 | D6: 121240000 | E6: 121240000 | F6: =E6-D6 -> 0 | G6: =E6/C6 -> 121240000
B7: 직원 (위촉직원 제외) | C7: 161 | D7: =D5-D6 -> 10893823892 | E7: =E5-E6 -> 10121910052 | F7: =E7-D7 -> -771913840 | G7: =E7/C7 -> 62869007
I8: 임원 인건비 = 원장(급여, 인상분, 제수당, 업무추진비)
B9: ※ 예산이월조서 인건비 244,810천원 반영 | I9: 직원 = 센터장, 정규직원(운영위촉, 과제위촉 제외)

Sheet 별첨7-2.계속비설명서(완료)
A1: <별첨 7-2> 계속비 설명서 | P1: (단위 : 천원)
A2: 부서 | B2: 예산과목 | C2: 사업명 | D2: 구분 | E2: 사업개요 | F2: 총 사업 비 | G2: 연차별 투자현황 및 투자계획 | P2: 비고
G3: 전전년도까지 | J3: 전년도 | M3: 당년도 예산액 | N3: 차년도 예산액 | O3: 차차년 도이후 예산액
G4: 예산액 | H4: 지출액 | I4: 지출 잔액 | J4: 예산액 | K4: 지출액 | L4: 지출 잔액
A5: 경영기획실 | B5: 운영비 | C5: 전남생물산업지원사업 성과활용사업 | D5: 기존(a) | E5: ◦ 전남생물산업진흥회 정기총회 및 임원회의, 분과 협의회 운영지원 ◦ 성과모니터링 및 성과관리시스템 운영 ◦ 기업지원, 세미나 및 워크숍 개최 ◦ 기업 전시회 참가지원 | F5: 271888000 | G5: 234181680 | H5: 234181680 | I5: 0 | J5: 37706320 | K5: 30481599 | L5: 7224721 | M5: 7224721 | N5: 0 | O5: 0
D6: 변경(b)
D7: 증감 (b-a)

Sheet 별첨7-3.예산이월총괄표(완료)
A1: <별첨7-3> 예산 이월 총괄표
A2: (단위 : 천원)
A3: 구 분 | B3: 합 계 | D3: 운영사업(보조금사업 포함) | F3: 대행사업 | H3: 자본예산 | J3: 비 고
B4: 건 수 | C4: 이월액 | D4: 건 수 | E4: 이월액 | F4: 건 수 | G4: 이월액 | H4: 건 수 | I4: 이월액
A5: 계 | B5: =SUM(B6:B12) -> 55 | C5: =SUM(C6:C12) -> #REF! | D5: =SUM(D6:D12) -> 11 | E5: =SUM(E6:E12) -> #REF! | F5: =SUM(F6:F12) -> 36 | G5: =SUM(G6:G12) -> #REF! | H5: =SUM(H6:H12) -> 8 | I5: =SUM(I6:I12) -> #REF! | J5: =SUM(J6:J12) -> 0
A6: 경영기획실 | B6: =D6+F6+H6 -> 3 | C6: =E6+G6+I6 -> #REF! | D6: 2 | E6: =SUM('별첨7-4.예산이월설명서(완료)'!#REF!) -> #REF! | F6: 1 | G6: ='별첨7-4.예산이월설명서(완료)'!#REF! -> #REF!
A7: 식품산업연구센터 | B7: =D7+F7+H7 -> 13 | C7: =E7+G7+I7 -> #REF! | F7: 10 | G7: =SUM('별첨7-4.예산이월설명서(완료)'!#REF!) -> #REF! | H7: 3 | I7: =SUM('별첨7-4.예산이월설명서(완료)'!#REF!) -> #REF!
A8: 생물의약연구센터 | B8: =D8+F8+H8 -> 14 | C8: =E8+G8+I8 -> #REF! | D8: 8 | E8: =SUM('별첨7-4.예산이월설명서(완료)'!#REF!) -> #REF! | F8: 3 | G8: =SUM('별첨7-4.예산이월설명서(완료)'!#REF!) -> #REF! | H8: 3 | I8: =SUM('별첨7-4.예산이월설명서(완료)'!#REF!) -> #REF!
A9: 나노바이오연구센터 | B9: =D9+F9+H9 -> 4 | C9: =E9+G9+I9 -> 3018721000 | F9: 3 | G9: =SUM('별첨7-4.예산이월설명서(완료)'!G5:G14) -> 75681000 | H9: 1 | I9: =SUM('별첨7-4.예산이월설명서(완료)'!G15:G15) -> 2943040000
A10: 천연자원연구센터 | B10: =D10+F10+H10 -> 14 | C10: =E10+G10+I10 -> #REF! | F10: 13 | G10: =SUM('별첨7-4.예산이월설명서(완료)'!#REF!) -> #REF! | H10: 1 | I10: ='별첨7-4.예산이월설명서(완료)'!#REF! -> #REF!
A11: 해양바이오연구센터 | B11: =D11+F11+H11 -> 5 | C11: =E11+G11+I11 -> #REF! | F11: 5 | G11: =SUM('별첨7-4.예산이월설명서(완료)'!#REF!) -> #REF!
A12: 친환경농생명연구센터 | B12: =D12+F12+H12 -> 2 | C12: =E12+G12+I12 -> #REF! | D12: 1 | E12: =SUM('별첨7-4.예산이월설명서(완료)'!#REF!) -> #REF! | F12: 1 | G12: =SUM('별첨7-4.예산이월설명서(완료)'!#REF!) -> #REF!

Sheet 별첨7-4.예산이월설명서(완료)
A1: <별첨 7-4> 예산 이월 설명서
G2: (단위 : 천원)
A3: 부서 | B3: 사업구분 | C3: 사업명 | D3: 이월내용 | E3: 예산액 | F3: 예산과목 | G3: 2025년 이월액 | H3: 사유
C4: ="계 : "&COUNTA(C5:C15) -> 계 : 4 | E4: =SUM(E5:E15) -> 3150000000 | G4: =SUM(G5:G15) -> 3018721000
A5: 나노센터 | B5: 대행사업 - 사업예산 | C5: 초임계의약품생산플랫폼구축(3차) | D5: 사업기간: ‘23.01~’27.12. 이월구성: 집행잔액 56,960천원 (기간제보수, 퇴직급여, 회의비, 국내여비, 국외여비) | E5: 56960000 | F5: 기간제근로자보수 | G5: 33600000 | H5: 사업기간 미도래
F6: 퇴직급여 | G6: 3360000
F7: 회의비 | G7: 5000000
F8: 국내여비 | G8: 5000000
F9: 국외업무여비 | G9: 10000000
A10: 나노센터-AI융합지원실 | B10: 대행사업 - 사업예산 | C10: 2024년 산업기술국제 협력사업(귀뚜라미) 2차년도 | D10: 사업기간 : '24.11.~'26.10. 이월구성 : 집행잔액 17,266천원 (기간제근로자보수, 사무관리비,국내여비) | E10: 100000000 | F10: 기간제근로자보수 | G10: 9923000 | H10: 사업기간 미도래
F11: 사무관리비 | G11: 7250000
F12: 국내여비 | G12: 93000
A13: 나노센터-AI융합지원실 | B13: 대행사업 - 사업예산 | C13: 2024년 산업기술국제 협력사업(귀뚜라미) 1차년도 | D13: 사업기간 : '24.11.~'26.10. 이월구성:집행잔액 1,455천원 (사무관리비, 회의비) | E13: 50000000 | F13: 사무관리비 | G13: 515000 | H13: 사업기간 미도래
F14: 회의비 | G14: 940000
A15: 나노센터 | B15: 대행사업 - 자본예산 | C15: 초임계의약품생산플랫폼구축(3차) | D15: 사업기간: ‘23.01~’27.12. - 이월구성: 집행잔액 2,943,040천원 (시설비) | E15: 2943040000 | F15: 시설비 | G15: 2943040000 | H15: 사업기간 미도래

Sheet 별첨7-5.중요자산취득설명서(완료)
A1: <별첨 7-5> 1천만원 이상 중요자산의 취득 및 처분설명서
M2: (단위 : 토지/천㎡, 건물/㎡, 취득(처분)가액/백만원)
A3: 취 득 | B3: 자 산 종 별 | D3: 자산명 | E3: 취득계획 | H3: 처분계획
A4: (처 분) | C4: 부서 | E4: 취득 | F4: 수량 | G4: 평가액 | H4: 처분 | I4: 장부가액(a) | K4: 처분액(b) | M4: 처분손익
A5: 예정시기 | H5: 목적 | I5: 수량 | J5: 금액 | K5: 수량 | L5: 금액 | M5: (a-b)
A6: 계 | F6: =SUM(F7:F9) -> 6 | G6: =SUM(G7:G9) -> 4006000
A7: 2026년중 | B7: 공기구비품 | C7: 나노 | D7: PC | E7: 기업지원 | F7: 4 | G7: 6000
A8: 2026년중 | B8: 건물 | C8: 나노 | D8: 초임계 의약품 플랫폼 구축 | E8: 생산지원 | F8: 1 | G8: 1000000
A9: 2026년중 | B9: 기계장치 | C9: 나노 | D9: 초임계 유체 그래마토그래피 | E9: 연구개발 | F9: 1 | G9: 3000000
